Workbook

Sheet Enero
A1: n | C1: 45992 | D1: 45871 | E1: 45872 | F1: 45873 | G1: 45874 | H1: 45875 | I1: 45876 | J1: 45877 | K1: 45878 | L1: 45879 | M1: 45880 | N1: 45881 | O1: 45882 | P1: 45883 | Q1: 45884 | R1: 45885 | S1: 45886 | T1: 45887 | U1: 45888 | V1: 45889 | W1: 45890 | X1: 45891 | Y1: 45892 | Z1: 45893 | AA1: 45894 | AB1: 45895 | AC1: 45896 | AD1: 45897 | AE1: 45898 | AF1: 45899 | AG1: 45900 | AH1: Totales
A4: Ingresos
A5: Transbank | C5: =338308+252796+1158748 -> 1749852 | D5: =85094 -> 85094 | E5: =916940+66163+409746+62276 -> 1455125 | F5: =165710+665914+1146843+66462 -> 2044929 | G5: 1241627 | H5: =328154+28299+22320 -> 378773 | I5: =42064+731212+610411+25807 -> 1409494 | J5: =929067+562920+20526 -> 1512513 | K5: =761874+492440+12575+18335 -> 1285224 | L5: =590744+1150349+82663+6500+28700 -> 1858956 | M5: =164012+2005743+34456+541161 -> 2745372 | N5: =18633+308395+1111972 -> 1439000 | O5: =232286+45936 -> 278222 | P5: =18135+971916+62673+532669 -> 1585393 | Q5: =385159+603857+33805 -> 1022821 | R5: =833270+548534+9906+11693 -> 1403403 | S5: =92071+1216512+611996+38064 -> 1958643 | T5: =1710791+113993+444009+139202+21483 -> 2429478 | U5: =1301009+347355 -> 1648364 | V5: =294445+37402+90642 -> 422489 | W5: =98537+895436+564681+24594 -> 1583248 | X5: =110105+22250+1105+837440+524121 -> 1495021 | Y5: =99841+415619+4270+133323+13920 -> 666973 | Z5: =40226+43245+606190+33979+585213 -> 1308853 | AA5: =133521+125252+34476+1296338+513560 -> 2103147 | AB5: =264553+912968 -> 1177521 | AC5: =132560+122866 -> 255426 | AD5: =689243+673607+39659+57992 -> 1460501 | AE5: =612490+406077+30073+48348+135414 -> 1232402 | AF5: =526085+883898+78917 -> 1488900 | AG5: =1035920+102124+597956+86411+129436+32186 -> 1984033 | AH5: =SUM(C5:AG5) -> 42710797
A6: Transferencias | C6: 0 | D6: 28400 | E6: =35090+6200 -> 41290 | F6: 0 | G6: 29600 | H6: =8200+30400 -> 38600 | I6: 0 | J6: 0 | K6: 0 | L6: 0 | M6: 0 | N6: 25990 | O6: 0 | P6: 0 | Q6: 0 | R6: 0 | S6: 0 | T6: 0 | U6: 0 | V6: 0 | W6: 0 | X6: 0 | Y6: 30500 | Z6: 0 | AA6: 0 | AB6: 0 | AC6: 25690 | AD6: 0 | AE6: 0 | AF6: 0 | AG6: 0 | AH6: =SUM(C6:AG6) -> 220070
A7: Efectivo | C7: 0 | D7: 0 | E7: 0 | F7: 0 | G7: 0 | H7: 0 | I7: 0 | J7: 0 | K7: 0 | L7: 0 | M7: 0 | N7: 0 | O7: 380000 | P7: 0 | Q7: 0 | R7: 0 | S7: 0 | T7: 0 | U7: 0 | V7: 0 | W7: 0 | X7: 0 | Y7: 0 | Z7: 0 | AA7: 0 | AB7: 0 | AC7: 0 | AD7: 0 | AE7: 0 | AF7: 0 | AG7: 0 | AH7: =SUM(C7:AG7) -> 380000
A8: Uber | C8: 0 | D8: 0 | E8: 0 | F8: 0 | G8: 0 | H8: =481480+464285 -> 945765 | I8: 0 | J8: 0 | K8: 0 | L8: 0 | M8: 0 | N8: 0 | O8: =481617+103191 -> 584808 | P8: 0 | Q8: 0 | R8: 0 | S8: 0 | T8: 0 | U8: 0 | V8: 321048 | W8: 0 | X8: 0 | Y8: 0 | Z8: 0 | AA8: 0 | AB8: 0 | AC8: =168900+366611 -> 535511 | AD8: 0 | AE8: 0 | AF8: 0 | AG8: 0 | AH8: =SUM(C8:AG8) -> 2387132
A9: Total bruto | C9: =SUM(C5:C8) -> 1749852 | D9: =SUM(D5:D8) -> 113494 | E9: =SUM(E5:E8) -> 1496415 | F9: =SUM(F5:F8) -> 2044929 | G9: =SUM(G5:G8) -> 1271227 | H9: =SUM(H5:H8) -> 1363138 | I9: =SUM(I5:I8) -> 1409494 | J9: =SUM(J5:J8) -> 1512513 | ... AH9: =SUM(AH5:AH8) -> 45697999
A10: Total neto | AH10: =AH9-AH78 -> 39294269
A12: Materia prima | B12: =AH12/$AH$10 -> 0.31442746 | C12: =sum(C13:C29) -> 0 | D12: =sum(D13:D29) -> 1438566 | E12: =sum(E13:E29) -> 69320 | F12: =sum(F13:F29) -> 76500 | G12: =sum(G14:G29) -> 871050 | H12: =sum(H13:H29) -> 1042424 | I12: =sum(I13:I29) -> 257328 | J12: =sum(J13:J29) -> 102887 | K12: =sum(K13:K29) -> 397169 | L12: =sum(L13:L29) -> 99976 | M12: =sum(M13:M29) -> 72460 | N12: =sum(N13:N29) -> 859478 | O12: =sum(O13:O29) -> 1052873 | ... AH12: =sum(AH13:AH29) -> 12355197
A13: MP | B13: =AH13/$AH$10 -> 0.030696283 | C13: 0 | D13: =116000+58240+7200+11600 -> 193040 | E13: 69320 | F13: 0 | G13: 0 | H13: =12990 -> 12990 | I13: 6000 | J13: 0 | K13: 0 | L13: =90026+9950 -> 99976 | M13: 48480 | N13: 4500 | O13: 0 | P13: 0 | Q13: 0 | R13: 0 | S13: 21300 | T13: 0 | U13: 0 | V13: =77350+44300 -> 121650 | W13: =153986+49980 -> 203966 | X13: 0 | Y13: =52230 -> 52230 | Z13: =152897+13000 -> 165897 | AA13: 0 | AB13: 0 | AC13: =99008+3831 -> 102839 | AD13: 0 | AE13: =94000 -> 94000 | AF13: 10000 | AG13: 0 | AH13: =SUM(C13:AG13) -> 1206188
A14: Hod Food | B14: =AH14/$AH$10 -> 0.068520552 | C14: 0 | D14: 0 | E14: 0 | F14: 0 | G14: 736104 | H14: 0 | I14: 0 | J14: 0 | K14: 0 | L14: 0 | M14: 0 | N14: 324858 | O14: 0 | P14: 0 | Q14: 0 | R14: 0 | S14: 0 | T14: 0 | U14: 561478 | V14: 0 | W14: 0 | X14: 0 | Y14: 0 | Z14: 0 | AA14: 0 | AB14: 0 | AC14: 1070025 | AD14: 0 | AE14: 0 | AF14: 0 | AG14: 0 | AH14: =SUM(C14:AG14) -> 2692465
A15: Seitan | B15: =AH15/$AH$10 -> 0.0039187903 | C15: 0 | D15: 153986 | E15: 0 | F15: 0 | G15: 0 | H15: 0 | I15: 0 | J15: 0 | K15: 0 | L15: 0 | M15: 0 | N15: 0 | O15: 0 | P15: 0 | Q15: 0 | R15: 0 | S15: 0 | T15: 0 | U15: 0 | V15: 0 | W15: 0 | X15: 0 | Y15: 0 | Z15: 0 | AA15: 0 | AB15: 0 | AC15: 0 | AD15: 0 | AE15: 0 | AF15: 0 | AG15: 0 | AH15: =SUM(C15:AG15) -> 153986
A16: Palta | B16: =AH16/$AH$10 -> 0.045196311 | C16: 0 | D16: 830025 | E16: 0 | F16: 0 | G16: 0 | H16: 0 | I16: 0 | J16: 0 | K16: 0 | L16: 0 | M16: 0 | N16: 521220 | O16: 0 | P16: 0 | Q16: 0 | R16: 0 | S16: 0 | T16: 0 | U16: 0 | V16: 0 | W16: 0 | X16: 0 | Y16: 0 | Z16: 424711 | AA16: 0 | AB16: 0 | AC16: 0 | AD16: 0 | AE16: 0 | AF16: 0 | AG16: 0 | AH16: =SUM(C16:AG16) -> 1775956
A17: Carivo | B17: =AH17/$AH$10 -> 0.060522439 | C17: 0 | D17: 0 | E17: 0 | F17: 0 | G17: 0 | H17: 827125 | I17: 0 | J17: 0 | K17: 0 | L17: 0 | M17: 0 | N17: 0 | O17: 759110 | P17: 0 | Q17: 0 | R17: 0 | S17: 0 | T17: 0 | U17: 0 | V17: 791950 | W17: 0 | X17: 0 | Y17: 0 | Z17: 0 | AA17: 0 | AB17: 0 | AC17: 0 | AD17: 0 | AE17: 0 | AF17: 0 | AG17: 0 | AH17: =SUM(C17:AG17) -> 2378185
A18: Shen | B18: =AH18/$AH$10 -> 0.018412863 | C18: 0 | D18: 0 | E18: 0 | F18: 76500 | G18: 0 | H18: 0 | I18: 0 | J18: 0 | K18: 206720 | L18: 0 | M18: 0 | N18: 0 | O18: 0 | P18: 159460 | Q18: 0 | R18: 0 | S18: 0 | T18: 0 | U18: 0 | V18: 0 | W18: 159460 | X18: 0 | Y18: 0 | Z18: 0 | AA18: 0 | AB18: 0 | AC18: 121380 | AD18: 0 | AE18: 0 | AF18: 0 | AG18: 0 | AH18: =SUM(C18:AG18) -> 723520
A19: Mozzen | B19: =AH19/$AH$10 -> 0.0094686836 | C19: 0 | D19: 0 | E19: 0 | F19: 0 | G19: 0 | H19: 0 | I19: 0 | J19: 0 | K19: 0 | L19: 0 | M19: 0 | N19: 0 | O19: 191185 | P19: 0 | Q19: 0 | R19: 0 | S19: 0 | T19: 0 | U19: 0 | V19: 0 | W19: 0 | X19: 0 | Y19: 0 | Z19: 0 | AA19: 0 | AB19: 0 | AC19: 0 | AD19: 180880 | AE19: 0 | AF19: 0 | AG19: 0 | AH19: =SUM(C19:AG19) -> 372065
A20: Café y Té | B20: =AH20/$AH$10 -> 0 | C20: 0 | D20: 0 | E20: 0 | F20: 0 | G20: 0 | H20: 0 | I20: 0 | J20: 0 | K20: 0 | L20: 0 | M20: 0 | N20: 0 | O20: 0 | P20: 0 | Q20: 0 | R20: 0 | S20: 0 | T20: 0 | U20: 0 | V20: 0 | W20: 0 | X20: 0 | Y20: 0 | Z20: 0 | AA20: 0 | AB20: 0 | AC20: 0 | AD20: 0 | AE20: 0 | AF20: 0 | AG20: 0 | AH20: =SUM(C20:AG20) -> 0
A21: Leche de soya | B21: =AH21/$AH$10 -> 0.0060447492 | C21: 0 | D21: 0 | E21: 0 | F21: 0 | G21: 134946 | H21: 0 | I21: 0 | J21: 0 | K21: 0 | L21: 0 | M21: 0 | N21: 0 | O21: 102578 | P21: 0 | Q21: 0 | R21: 0 | S21: 0 | T21: 0 | U21: 0 | V21: 0 | W21: 0 | X21: 0 | Y21: 0 | Z21: 0 | AA21: 0 | AB21: 0 | AC21: 0 | AD21: 0 | AE21: 0 | AF21: 0 | AG21: 0 | AH21: =SUM(C21:AG21) -> 237524
A22: Bebestibles | B22: =AH22/$AH$10 -> 0.0056767057 | C22: 0 | D22: 0 | E22: 0 | F22: 0 | G22: 0 | H22: =23205+2200 -> 25405 | I22: 0 | J22: 0 | K22: 0 | L22: 0 | M22: 19480 | N22: 0 | O22: 0 | P22: 46410 | Q22: 0 | R22: 0 | S22: 0 | T22: 0 | U22: 0 | V22: 23205 | W22: 0 | X22: 0 | Y22: =61152+46410 -> 107562 | Z22: 0 | AA22: 0 | AB22: 0 | AC22: 0 | AD22: 0 | AE22: 1000 | AF22: 0 | AG22: 0 | AH22: =SUM(C22:AG22) -> 223062
A23: Brugga | B23: =AH23/$AH$10 -> 0.01758913 | C23: 0 | D23: 0 | E23: 0 | F23: 0 | G23: 0 | H23: 0 | I23: 251328 | J23: 0 | K23: 0 | L23: 0 | M23: 0 | N23: 0 | O23: 0 | P23: 0 | Q23: 0 | R23: 0 | S23: 0 | T23: 0 | U23: 0 | V23: 157080 | W23: 0 | X23: 0 | Y23: 0 | Z23: 0 | AA23: 0 | AB23: 0 | AC23: 0 | AD23: 0 | AE23: 0 | AF23: 282744 | AG23: 0 | AH23: =SUM(C23:AG23) -> 691152
A24: Colación | B24: =AH24/$AH$10 -> 0.0099126415 | C24: 0 | D24: =12000+37778 -> 49778 | E24: 0 | F24: 0 | G24: 0 | H24: 47187 | I24: 0 | J24: 28887 | K24: 0 | L24: 0 | M24: 4500 | N24: 8900 | O24: 0 | P24: 0 | Q24: 0 | R24: 44636 | S24: 0 | T24: 0 | U24: 8000 | V24: 39940 | W24: 0 | X24: 0 | Y24: 51856 | Z24: 6700 | AA24: 0 | AB24: =12570 -> 12570 | AC24: 86556 | AD24: 0 | AE24: 0 | AF24: 0 | AG24: 0 | AH24: =SUM(C24:AG24) -> 389510
A25: Empaques y desechables | B25: =AH25/$AH$10 -> 0.017401062 | C25: 0 | D25: =199057+8000+4680 -> 211737 | E25: 0 | F25: 0 | G25: 0 | H25: 39720 | I25: 0 | J25: 0 | K25: 12839 | L25: 0 | M25: 0 | N25: 0 | O25: 0 | P25: 167879 | Q25: 0 | R25: 27400 | S25: 0 | T25: 0 | U25: 0 | V25: =68019+13070 -> 81089 | W25: 0 | X25: 0 | Y25: 0 | Z25: 0 | AA25: 0 | AB25: 0 | AC25: 0 | AD25: 0 | AE25: 143098 | AF25: 0 | AG25: 0 | AH25: =SUM(C25:AG25) -> 683762
A26: Soyas sachet | B26: =AH26/$AH$10 -> 0.004580668 | C26: 0 | D26: 0 | E26: 0 | F26: 0 | G26: 0 | H26: 89997 | I26: 0 | J26: 0 | K26: 0 | L26: 0 | M26: 0 | N26: 0 | O26: 0 | P26: 0 | Q26: 0 | R26: 0 | S26: 0 | T26: 0 | U26: 0 | V26: 0 | W26: 0 | X26: 89997 | Y26: 0 | Z26: 0 | AA26: 0 | AB26: 0 | AC26: 0 | AD26: 0 | AE26: 0 | AF26: 0 | AG26: 0 | AH26: =SUM(C26:AG26) -> 179994
A27: Servilletas | B27: =AH27/$AH$10 -> 0 | C27: 0 | D27: 0 | E27: 0 | F27: 0 | G27: 0 | H27: 0 | I27: 0 | J27: 0 | K27: 0 | L27: 0 | M27: 0 | N27: 0 | O27: 0 | P27: 0 | Q27: 0 | R27: 0 | S27: 0 | T27: 0 | U27: 0 | V27: 0 | W27: 0 | X27: 0 | Y27: 0 | Z27: 0 | AA27: 0 | AB27: 0 | AC27: 0 | AD27: 0 | AE27: 0 | AF27: 0 | AG27: 0 | AH27: =SUM(C27:AG27) -> 0
A28: Limpieza e higiene | B28: =AH28/$AH$10 -> 0 | C28: 0 | D28: 0 | E28: 0 | F28: 0 | G28: 0 | H28: 0 | I28: 0 | J28: 0 | K28: 0 | L28: 0 | M28: 0 | N28: 0 | O28: 0 | P28: 0 | Q28: 0 | R28: 0 | S28: 0 | T28: 0 | U28: 0 | V28: 0 | W28: 0 | X28: 0 | Y28: 0 | Z28: 0 | AA28: 0 | AB28: 0 | AC28: 0 | AD28: 0 | AE28: 0 | AF28: 0 | AG28: 0 | AH28: =SUM(C28:AG28) -> 0
A29: Postres | B29: =AH29/$AH$10 -> 0.016486577 | C29: 0 | D29: 0 | E29: 0 | F29: 0 | G29: 0 | H29: 0 | I29: 0 | J29: 74000 | K29: 177610 | L29: 0 | M29: 0 | N29: 0 | O29: 0 | P29: 0 | Q29: 0 | R29: 0 | S29: 0 | T29: 0 | U29: 0 | V29: 0 | W29: 235218 | X29: 0 | Y29: 0 | Z29: =74000+13000 -> 87000 | AA29: 0 | AB29: 0 | AC29: 0 | AD29: 0 | AE29: 74000 | AF29: 0 | AG29: 0 | AH29: =SUM(C29:AG29) -> 647828
A31: Gastos FV | B31: =AH31/$AH$10 -> 0.2216496 | C31: =sum(C32+C51+C61) -> 0 | D31: =sum(D32+D51+D61) -> 614000 | E31: =sum(E32+E51+E61) -> 58245 | F31: =sum(F32+F51+F61) -> 0 | G31: =sum(G32+G51+G61) -> 276088 | H31: =sum(H32+H51+H61) -> 210771 | I31: =sum(I32+I51+I61) -> 1945512 | J31: =sum(J32+J51+J61) -> 100000 | ... AH31: =sum(AH32+AH51+AH61) -> 8709559
A32: Operaciones | B32: =AH32/$AH$10 -> 0.16157361 | C32: =sum(C33:C50) -> 0 | D32: =sum(D33:D50) -> 0 | E32: =sum(E33:E50) -> 0 | F32: =sum(F33:F50) -> 0 | G32: =sum(G33:G50) -> 167310 | H32: =sum(H33:H50) -> 121071 | I32: =sum(I33:I50) -> 1945512 | J32: =sum(J33:J50) -> 100000 | ... AH32: =sum(AH33:AH50) -> 6348917
A33: Electricidad | B33: =AH33/$AH$10 -> 0.0040682777 | C33: 0 | D33: 0 | E33: 0 | F33: 0 | G33: 0 | H33: 0 | I33: 0 | J33: 0 | K33: 0 | L33: 0 | M33: 0 | N33: 0 | O33: 0 | P33: 0 | Q33: 0 | R33: 159860 | S33: 0 | T33: 0 | U33: 0 | V33: 0 | W33: 0 | X33: 0 | Y33: 0 | Z33: 0 | AA33: 0 | AB33: 0 | AC33: 0 | AD33: 0 | AE33: 0 | AF33: 0 | AG33: 0 | AH33: =SUM(C33:AG33) -> 159860
A34: Agua | B34: =AH34/$AH$10 -> 0.0035797841 | C34: 0 | D34: 0 | E34: 0 | F34: 0 | G34: 0 | H34: 0 | I34: 0 | J34: 0 | K34: 0 | L34: 0 | M34: 0 | N34: 0 | O34: 0 | P34: 0 | Q34: 0 | R34: 140665 | S34: 0 | T34: 0 | U34: 0 | V34: 0 | W34: 0 | X34: 0 | Y34: 0 | Z34: 0 | AA34: 0 | AB34: 0 | AC34: 0 | AD34: 0 | AE34: 0 | AF34: 0 | AG34: 0 | AH34: =SUM(C34:AG34) -> 140665
A35: Gas | B35: =AH35/$AH$10 -> 0.0094866251 | C35: 0 | D35: 0 | E35: 0 | F35: 0 | G35: 0 | H35: 0 | I35: 0 | J35: 0 | K35: 0 | L35: 0 | M35: 0 | N35: 0 | O35: 0 | P35: 0 | Q35: 0 | R35: 372770 | S35: 0 | T35: 0 | U35: 0 | V35: 0 | W35: 0 | X35: 0 | Y35: 0 | Z35: 0 | AA35: 0 | AB35: 0 | AC35: 0 | AD35: 0 | AE35: 0 | AF35: 0 | AG35: 0 | AH35: =SUM(C35:AG35) -> 372770
A36: Restaurantpe | B36: =AH36/$AH$10 -> 0 | C36: 0 | D36: 0 | E36: 0 | F36: 0 | G36: 0 | H36: 0 | I36: 0 | J36: 0 | K36: 0 | L36: 0 | M36: 0 | N36: 0 | O36: 0 | P36: 0 | Q36: 0 | R36: 0 | S36: 0 | T36: 0 | U36: 0 | V36: 0 | W36: 0 | X36: 0 | Y36: 0 | Z36: 0 | AA36: 0 | AB36: 0 | AC36: 0 | AD36: 0 | AE36: 0 | AF36: 0 | AG36: 0 | AH36: =SUM(C36:AG36) -> 0
A37: Toteat | B37: =AH37/$AH$10 -> 0.0052056192 | C37: 0 | D37: 0 | E37: 0 | F37: 0 | G37: 0 | H37: 109554 | I37: 0 | J37: 0 | K37: 0 | L37: 0 | M37: 94997 | N37: 0 | O37: 0 | P37: 0 | Q37: 0 | R37: 0 | S37: 0 | T37: 0 | U37: 0 | V37: 0 | W37: 0 | X37: 0 | Y37: 0 | Z37: 0 | AA37: 0 | AB37: 0 | AC37: 0 | AD37: 0 | AE37: 0 | AF37: 0 | AG37: 0 | AH37: =SUM(C37:AG37) -> 204551
A38: Alarma | B38: =AH38/$AH$10 -> 0.0012152917 | C38: 0 | D38: 0 | E38: 0 | F38: 0 | G38: 0 | H38: 0 | I38: 0 | J38: 0 | K38: 0 | L38: 0 | M38: 0 | N38: 0 | O38: 0 | P38: 0 | Q38: 0 | R38: 0 | S38: 0 | T38: 0 | U38: 0 | V38: 0 | W38: 0 | X38: 0 | Y38: 0 | Z38: 0 | AA38: 0 | AB38: 0 | AC38: 0 | AD38: 47754 | AE38: 0 | AF38: 0 | AG38: 0 | AH38: =SUM(C38:AG38) -> 47754
A39: VTR | B39: =AH39/$AH$10 -> 0.00029309618 | C39: 0 | D39: 0 | E39: 0 | F39: 0 | G39: 0 | H39: 11517 | I39: 0 | J39: 0 | K39: 0 | L39: 0 | M39: 0 | N39: 0 | O39: 0 | P39: 0 | Q39: 0 | R39: 0 | S39: 0 | T39: 0 | U39: 0 | V39: 0 | W39: 0 | X39: 0 | Y39: 0 | Z39: 0 | AA39: 0 | AB39: 0 | AC39: 0 | AD39: 0 | AE39: 0 | AF39: 0 | AG39: 0 | AH39: =SUM(C39:AG39) -> 11517
A40: Bodega | B40: =AH40/$AH$10 -> 0.0076347011 | C40: 0 | D40: 0 | E40: 0 | F40: 0 | G40: 0 | H40: 0 | I40: 0 | J40: 0 | K40: 0 | L40: 0 | M40: 0 | N40: 0 | O40: 0 | P40: 0 | Q40: 0 | R40: 0 | S40: 0 | T40: 300000 | U40: 0 | V40: 0 | W40: 0 | X40: 0 | Y40: 0 | Z40: 0 | AA40: 0 | AB40: 0 | AC40: 0 | AD40: 0 | AE40: 0 | AF40: 0 | AG40: 0 | AH40: =SUM(C40:AG40) -> 300000
A41: Arriendo | B41: =AH41/$AH$10 -> 0.046512177 | C41: 0 | D41: 0 | E41: 0 | F41: 0 | G41: 0 | H41: 0 | I41: 1827662 | J41: 0 | K41: 0 | L41: 0 | M41: 0 | N41: 0 | O41: 0 | P41: 0 | Q41: 0 | R41: 0 | S41: 0 | T41: 0 | U41: 0 | V41: 0 | W41: 0 | X41: 0 | Y41: 0 | Z41: 0 | AA41: 0 | AB41: 0 | AC41: 0 | AD41: 0 | AE41: 0 | AF41: 0 | AG41: 0 | AH41: =SUM(C41:AG41) -> 1827662
A42: Funmigacion | B42: =AH42/$AH$10 -> 0.0029991651 | C42: 0 | D42: 0 | E42: 0 | F42: 0 | G42: 0 | H42: 0 | I42: 117850 | J42: 0 | K42: 0 | L42: 0 | M42: 0 | N42: 0 | O42: 0 | P42: 0 | Q42: 0 | R42: 0 | S42: 0 | T42: 0 | U42: 0 | V42: 0 | W42: 0 | X42: 0 | Y42: 0 | Z42: 0 | AA42: 0 | AB42: 0 | AC42: 0 | AD42: 0 | AE42: 0 | AF42: 0 | AG42: 0 | AH42: =SUM(C42:AG42) -> 117850
A43: Reposición de vasos | B43: =AH43/$AH$10 -> 0 | C43: 0 | D43: 0 | E43: 0 | F43: 0 | G43: 0 | H43: 0 | I43: 0 | J43: 0 | K43: 0 | L43: 0 | M43: 0 | N43: 0 | O43: 0 | P43: 0 | Q43: 0 | R43: 0 | S43: 0 | T43: 0 | U43: 0 | V43: 0 | W43: 0 | X43: 0 | Y43: 0 | Z43: 0 | AA43: 0 | AB43: 0 | AC43: 0 | AD43: 0 | AE43: 0 | AF43: 0 | AG43: 0 | AH43: =SUM(C43:AG43) -> 0
A44: Reposición Articulos cocina | B44: =AH44/$AH$10 -> 0.0047640535 | C44: 0 | D44: 0 | E44: 0 | F44: 0 | G44: 0 | H44: 0 | I44: 0 | J44: 100000 | K44: 0 | L44: 87200 | M44: 0 | N44: 0 | O44: 0 | P44: 0 | Q44: 0 | R44: 0 | S44: 0 | T44: 0 | U44: 0 | V44: 0 | W44: 0 | X44: 0 | Y44: 0 | Z44: 0 | AA44: 0 | AB44: 0 | AC44: 0 | AD44: 0 | AE44: 0 | AF44: 0 | AG44: 0 | AH44: =SUM(C44:AG44) -> 187200
...

Sheet Febrero
C1: 46054 | D1: 46055 | E1: 46056 | F1: 46057 | G1: 46058 | H1: 46059 | I1: 46060 | J1: 46061 | K1: 46062 | L1: 46063 | M1: 46064 | N1: 46065 | O1: 46066 | P1: 46067 | Q1: 46068 | R1: 46069 | S1: 46070 | T1: 46071 | U1: 46072 | V1: 46073 | W1: 46074 | X1: 46075 | Y1: 46076 | Z1: 46077 | AA1: 46078 | AB1: 46079 | AC1: 46080 | AD1: 46081 | AH1: Totales
A4: Ingresos
A5: Transbank | C5: =725798+92172+1865686+103529 -> 2787185 | D5: =43046+328722+919735 -> 1291503 | E5: =283773+6429+109208 -> 399410 | F5: =501293+497082+36768 -> 1035143 | G5: =31387+407140+852452 -> 1290979 | H5: =16740+115287+842050+298200+66318 -> 1338595 | I5: =690028+948920+54704+101038 -> 1794690 | J5: =1879480+356821+13044+151059 -> 2400404 | K5: =16077+50420+112995+1272072 -> 1451564 | L5: =174783+22155 -> 196938 | M5: =961673+486327+62775 -> 1510775 | N5: =510510+28598+700772+44441 -> 1284321 | O5: =1066903+420475+38063+22918 -> 1548359 | P5: =1841432+542189+77838+309234+89780 -> 2860473 | Q5: =1093084+145579+5112454+154447 -> 6505564 | R5: =96056+945234+83500 -> 1124790 | S5: 0 | T5: =1088481+675658+13850+87985+59900 -> 1925874 | U5: =495288+711135+28796+31844 -> 1267063 | V5: =309673+831214+58591+59287 -> 1258765 | W5: =855924+541260 -> 1397184 | X5: =1240654+437617+152554+17647 -> 1848472 | Y5: =61266+81011+1153557+112597 -> 1408431 | Z5: =131160+27102 -> 158262 | AA5: =531477+484645+209554 -> 1225676 | AB5: =34480+639559+99842+495326 -> 1269207 | AC5: =630927+23108+278392+86988+29346 -> 1048761 | AD5: =184976+448384+922398 -> 1555758 | AE5: 0 | AF5: 0 | AG5: 0 | AH5: =SUM(C5:AG5) -> 43184146
A6: Transferencias | C6: 28250 | D6: 0 | E6: =277400+44400 -> 321800 | F6: 35050 | G6: 0 | H6: 0 | I6: 16150 | J6: 0 | K6: 0 | L6: 5900 | M6: 0 | N6: 0 | O6: 0 | P6: 24900 | Q6: 0 | R6: 0 | S6: 0 | T6: 0 | U6: 0 | V6: 0 | W6: 21500 | X6: 36960 | Y6: 0 | Z6: 41950 | AA6: 0 | AB6: 34950 | AC6: 0 | AD6: 0 | AE6: 0 | AF6: 0 | AG6: 0 | AH6: =SUM(C6:AG6) -> 567410
A7: Efectivo | C7: 0 | D7: 0 | E7: 0 | F7: 0 | G7: 0 | H7: 0 | I7: 0 | J7: 0 | K7: 0 | L7: 0 | M7: 0 | N7: 0 | O7: 0 | P7: 0 | Q7: 0 | R7: 0 | S7: 0 | T7: 0 | U7: 250000 | V7: 0 | W7: 0 | X7: 0 | Y7: 0 | Z7: 0 | AA7: 0 | AB7: 0 | AC7: 0 | AD7: 0 | AE7: 0 | AF7: 0 | AG7: 0 | AH7: =SUM(C7:AG7) -> 250000
A8: Uber | C8: 0 | D8: 0 | E8: =148415+357124 -> 505539 | F8: 0 | G8: 0 | H8: 0 | I8: 0 | J8: 0 | K8: 0 | L8: =392255+29139 -> 421394 | M8: 0 | N8: 0 | O8: 0 | P8: 0 | Q8: 0 | R8: 0 | S8: =63918+437417 -> 501335 | T8: 0 | U8: 0 | V8: 0 | W8: 0 | X8: 0 | Y8: 0 | Z8: =205876+497780 -> 703656 | AA8: 0 | AB8: 0 | AC8: 0 | AD8: 0 | AE8: 0 | AF8: 0 | AG8: 0 | AH8: =SUM(C8:AG8) -> 2131924
A9: Total bruto | C9: =SUM(C5:C8) -> 2815435 | D9: =SUM(D5:D8) -> 1291503 | E9: =SUM(E5:E8) -> 1226749 | F9: =SUM(F5:F8) -> 1070193 | G9: =SUM(G5:G8) -> 1290979 | H9: =SUM(H5:H8) -> 1338595 | I9: =SUM(I5:I8) -> 1810840 | J9: =SUM(J5:J8) -> 2400404 | ... AH9: =SUM(AH5:AH8) -> 46133480
A10: Total neto | AH10: =AH9-AH81 -> 41645305
A12: Materia prima | B12: =AH12/$AH$10 -> 0.33242864 | C12: =sum(C13:C30) -> 827960 | D12: =sum(D13:D30) -> 170940 | E12: =sum(E13:E30) -> 746417 | F12: =sum(F13:F30) -> 156836 | G12: =sum(G13:G30) -> 843785 | H12: =sum(H13:H30) -> 225690 | I12: =sum(I13:I30) -> 176918 | J12: =sum(J13:J30) -> 31250 | ... AH12: =sum(AH13:AH30) -> 13844092
A13: MP | B13: =AH13/$AH$10 -> 0.042422645 | C13: 5770 | D13: 43410 | E13: =30000 -> 30000 | F13: 21890 | G13: 77926 | H13: 25770 | I13: =25000+46410+20700 -> 92110 | J13: =5470+25780 -> 31250 | K13: =77350+171360+24156 -> 272866 | L13: 19900 | M13: =153986+84000+42000 -> 279986 | N13: 13256 | O13: 49730 | P13: =50000+57820 -> 107820 | Q13: 103320 | R13: 0 | S13: 28020 | T13: =166600+9540 -> 176140 | U13: 0 | V13: 84000 | W13: 0 | X13: 0 | Y13: 0 | Z13: 0 | AA13: =10000+17650 -> 27650 | AB13: 0 | AC13: =120190+91200 -> 211390 | AD13: =56500+8000 -> 64500 | AE13: 0 | AF13: 0 | AG13: 0 | AH13: =SUM(C13:AG13) -> 1766704
A14: Arroz | B14: =AH14/$AH$10 -> 0.011838069 | C14: 0 | D14: 116000 | E14: 0 | F14: 0 | G14: 116000 | H14: 0 | I14: 0 | J14: 0 | K14: 0 | L14: 0 | M14: 0 | N14: 0 | O14: 0 | P14: 0 | Q14: 0 | R14: 116000 | S14: 0 | T14: 0 | U14: 0 | V14: 0 | W14: 0 | X14: 0 | Y14: 0 | Z14: 145000 | AA14: 0 | AB14: 0 | AC14: 0 | AD14: 0 | AE14: 0 | AF14: 0 | AG14: 0 | AH14: =SUM(C14:AG14) -> 493000
A15: Hod Food | B15: =AH15/$AH$10 -> 0.066829646 | C15: 0 | D15: 0 | E15: 625666 | F15: 0 | G15: 0 | H15: 0 | I15: 0 | J15: 0 | K15: 0 | L15: 558624 | M15: 0 | N15: 0 | O15: 0 | P15: 0 | Q15: 0 | R15: 0 | S15: 0 | T15: 0 | U15: 919138 | V15: 0 | W15: 0 | X15: 0 | Y15: 0 | Z15: 679713 | AA15: 0 | AB15: 0 | AC15: 0 | AD15: 0 | AE15: 0 | AF15: 0 | AG15: 0 | AH15: =SUM(C15:AG15) -> 2783141
A16: Seitan | B16: =AH16/$AH$10 -> 0 | C16: 0 | D16: 0 | E16: 0 | F16: 0 | G16: 0 | H16: 0 | I16: 0 | J16: 0 | K16: 0 | L16: 0 | M16: 0 | N16: 0 | O16: 0 | P16: 0 | Q16: 0 | R16: 0 | S16: 0 | T16: 0 | U16: 0 | V16: 0 | W16: 0 | X16: 0 | Y16: 0 | Z16: 0 | AA16: 0 | AB16: 0 | AC16: 0 | AD16: 0 | AE16: 0 | AF16: 0 | AG16: 0 | AH16: =SUM(C16:AG16) -> 0
A17: Palta | B17: =AH17/$AH$10 -> 0.059100948 | C17: 0 | D17: 0 | E17: 0 | F17: 0 | G17: 649859 | H17: 0 | I17: 0 | J17: 0 | K17: 0 | L17: 0 | M17: 0 | N17: 0 | O17: 0 | P17: 0 | Q17: 0 | R17: 0 | S17: 0 | T17: 639625 | U17: 0 | V17: 0 | W17: 0 | X17: 0 | Y17: 0 | Z17: 747082 | AA17: 0 | AB17: 0 | AC17: 0 | AD17: 424711 | AE17: 0 | AF17: 0 | AG17: 0 | AH17: =SUM(C17:AG17) -> 2461277
A18: Carivo | B18: =AH18/$AH$10 -> 0.065863007 | C18: 814620 | D18: 0 | E18: 0 | F18: 0 | G18: 0 | H18: 0 | I18: 0 | J18: 0 | K18: 0 | L18: 647690 | M18: 0 | N18: 0 | O18: 0 | P18: 0 | Q18: 0 | R18: 0 | S18: 784975 | T18: 0 | U18: 0 | V18: 0 | W18: 0 | X18: 0 | Y18: 0 | Z18: 376600 | AA18: 0 | AB18: 0 | AC18: 0 | AD18: 119000 | AE18: 0 | AF18: 0 | AG18: 0 | AH18: =SUM(C18:AG18) -> 2742885
A19: Shen | B19: =AH19/$AH$10 -> 0.01062977 | C19: 0 | D19: 0 | E19: 0 | F19: 0 | G19: 0 | H19: 199920 | I19: 0 | J19: 0 | K19: 0 | L19: 0 | M19: 0 | N19: 0 | O19: 121380 | P19: 0 | Q19: 0 | R19: 0 | S19: 0 | T19: 0 | U19: 0 | V19: 0 | W19: 0 | X19: 0 | Y19: 0 | Z19: 121380 | AA19: 0 | AB19: 0 | AC19: 0 | AD19: 0 | AE19: 0 | AF19: 0 | AG19: 0 | AH19: =SUM(C19:AG19) -> 442680
A20: Mozzen | B20: =AH20/$AH$10 -> 0 | C20: 0 | D20: 0 | E20: 0 | F20: 0 | G20: 0 | H20: 0 | I20: 0 | J20: 0 | K20: 0 | L20: 0 | M20: 0 | N20: 0 | O20: 0 | P20: 0 | Q20: 0 | R20: 0 | S20: 0 | T20: 0 | U20: 0 | V20: 0 | W20: 0 | X20: 0 | Y20: 0 | Z20: 0 | AA20: 0 | AB20: 0 | AC20: 0 | AD20: 0 | AE20: 0 | AF20: 0 | AG20: 0 | AH20: =SUM(C20:AG20) -> 0
A21: Café y Té | B21: =AH21/$AH$10 -> 0 | C21: 0 | D21: 0 | E21: 0 | F21: 0 | G21: 0 | H21: 0 | I21: 0 | J21: 0 | K21: 0 | L21: 0 | M21: 0 | N21: 0 | O21: 0 | P21: 0 | Q21: 0 | R21: 0 | S21: 0 | T21: 0 | U21: 0 | V21: 0 | W21: 0 | X21: 0 | Y21: 0 | Z21: 0 | AA21: 0 | AB21: 0 | AC21: 0 | AD21: 0 | AE21: 0 | AF21: 0 | AG21: 0 | AH21: =SUM(C21:AG21) -> 0
A22: Leche de soya | B22: =AH22/$AH$10 -> 0.0060749705 | C22: 0 | D22: 0 | E22: 0 | F22: 134946 | G22: 0 | H22: 0 | I22: 0 | J22: 0 | K22: 0 | L22: 0 | M22: 0 | N22: 0 | O22: 0 | P22: 0 | Q22: 0 | R22: 0 | S22: 0 | T22: 0 | U22: 0 | V22: 0 | W22: 0 | X22: 0 | Y22: 0 | Z22: 118048 | AA22: 0 | AB22: 0 | AC22: 0 | AD22: 0 | AE22: 0 | AF22: 0 | AG22: 0 | AH22: =SUM(C22:AG22) -> 252994
A23: Bebestibles | B23: =AH23/$AH$10 -> 0.0063777417 | C23: 0 | D23: 0 | E23: 0 | F23: 0 | G23: 0 | H23: 0 | I23: 0 | J23: 0 | K23: 23000 | L23: 56089 | M23: 0 | N23: 0 | O23: 0 | P23: 0 | Q23: 0 | R23: 16501 | S23: 0 | T23: 0 | U23: 0 | V23: 0 | W23: 0 | X23: 0 | Y23: =23205+127307 -> 150512 | Z23: 19501 | AA23: 0 | AB23: 0 | AC23: 0 | AD23: 0 | AE23: 0 | AF23: 0 | AG23: 0 | AH23: =SUM(C23:AG23) -> 265603
A24: Brugga | B24: =AH24/$AH$10 -> 0.011872767 | C24: 0 | D24: 0 | E24: 0 | F24: 0 | G24: 0 | H24: 0 | I24: 0 | J24: 0 | K24: 0 | L24: 157080 | M24: 0 | N24: 157080 | O24: 0 | P24: 0 | Q24: 0 | R24: 0 | S24: 23205 | T24: 0 | U24: 0 | V24: 0 | W24: 0 | X24: 0 | Y24: 0 | Z24: 0 | AA24: 157080 | AB24: 0 | AC24: 0 | AD24: 0 | AE24: 0 | AF24: 0 | AG24: 0 | AH24: =SUM(C24:AG24) -> 494445
A25: Colación | B25: =AH25/$AH$10 -> 0.0079341957 | C25: 7570 | D25: 11530 | E25: 90751 | F25: 0 | G25: 0 | H25: 0 | I25: 84808 | J25: 0 | K25: 0 | L25: 0 | M25: 0 | N25: 0 | O25: 0 | P25: 0 | Q25: =37318 -> 37318 | R25: 0 | S25: 37160 | T25: 0 | U25: 0 | V25: 0 | W25: 0 | X25: 0 | Y25: 15180 | Z25: 0 | AA25: 0 | AB25: 46105 | AC25: 0 | AD25: 0 | AE25: 0 | AF25: 0 | AG25: 0 | AH25: =SUM(C25:AG25) -> 330422
A26: Empaques y desechables | B26: =AH26/$AH$10 -> 0.0094199334 | C26: 0 | D26: 0 | E26: 0 | F26: 0 | G26: 0 | H26: 0 | I26: 0 | J26: 0 | K26: 0 | L26: 160168 | M26: 0 | N26: 0 | O26: 0 | P26: 0 | Q26: 0 | R26: 0 | S26: 0 | T26: 160168 | U26: 0 | V26: 0 | W26: 0 | X26: 0 | Y26: 71960 | Z26: 0 | AA26: 0 | AB26: 0 | AC26: 0 | AD26: 0 | AE26: 0 | AF26: 0 | AG26: 0 | AH26: =SUM(C26:AG26) -> 392296
A27: Soyas sachet | B27: =AH27/$AH$10 -> 0.0043220718 | C27: 0 | D27: 0 | E27: 0 | F27: 0 | G27: 0 | H27: 0 | I27: 0 | J27: 0 | K27: 89997 | L27: 0 | M27: 0 | N27: 0 | O27: 0 | P27: 0 | Q27: 0 | R27: 0 | S27: 0 | T27: 0 | U27: 0 | V27: 0 | W27: 0 | X27: 0 | Y27: 0 | Z27: 89997 | AA27: 0 | AB27: 0 | AC27: 0 | AD27: 0 | AE27: 0 | AF27: 0 | AG27: 0 | AH27: =SUM(C27:AG27) -> 179994
A28: Servilletas | B28: =AH28/$AH$10 -> 0.0079551825 | C28: 0 | D28: 0 | E28: 0 | F28: 0 | G28: 0 | H28: 0 | I28: 0 | J28: 0 | K28: 0 | L28: 0 | M28: 248472 | N28: 0 | O28: 0 | P28: 0 | Q28: 0 | R28: 0 | S28: 0 | T28: 0 | U28: 0 | V28: 82824 | W28: 0 | X28: 0 | Y28: 0 | Z28: 0 | AA28: 0 | AB28: 0 | AC28: 0 | AD28: 0 | AE28: 0 | AF28: 0 | AG28: 0 | AH28: =SUM(C28:AG28) -> 331296
A29: Limpieza e higiene | B29: =AH29/$AH$10 -> 0 | C29: 0 | D29: 0 | E29: 0 | F29: 0 | G29: 0 | H29: 0 | I29: 0 | J29: 0 | K29: 0 | L29: 0 | M29: 0 | N29: 0 | O29: 0 | P29: 0 | Q29: 0 | R29: 0 | S29: 0 | T29: 0 | U29: 0 | V29: 0 | W29: 0 | X29: 0 | Y29: 0 | Z29: 0 | AA29: 0 | AB29: 0 | AC29: 0 | AD29: 0 | AE29: 0 | AF29: 0 | AG29: 0 | AH29: =SUM(C29:AG29) -> 0
A30: Postres | B30: =AH30/$AH$10 -> 0.02178769 | C30: 0 | D30: 0 | E30: 0 | F30: 0 | G30: 0 | H30: 0 | I30: 0 | J30: 0 | K30: 77200 | L30: 76715 | M30: 177610 | N30: 0 | O30: 0 | P30: 0 | Q30: 0 | R30: 89400 | S30: 148812 | T30: 0 | U30: 0 | V30: 96400 | W30: 0 | X30: 0 | Y30: 0 | Z30: 0 | AA30: 0 | AB30: 0 | AC30: 0 | AD30: 241218 | AE30: 0 | AF30: 0 | AG30: 0 | AH30: =SUM(C30:AG30) -> 907355
A32: Gastos FV | B32: =AH32/$AH$10 -> 0.20759041 | C32: =sum(C33+C53+C63) -> 0 | D32: =sum(D33+D53+D63) -> 0 | E32: =sum(E33+E53+E63) -> 58245 | F32: =sum(F33+F53+F63) -> 0 | G32: =sum(G33+G53+G63) -> 13000 | H32: =sum(H33+H53+H63) -> 2385298 | I32: =sum(I33+I53+I63) -> 0 | J32: =sum(J33+J53+J63) -> 345576 | ... AH32: =sum(AH33+AH53+AH63) -> 8645166
A33: Operaciones | B33: =AH33/$AH$10 -> 0.17458218 | C33: =sum(C34:C52) -> 0 | D33: =sum(D34:D52) -> 0 | E33: =sum(E34:E52) -> 0 | F33: =sum(F34:F52) -> 0 | G33: =sum(G34:G52) -> 0 | H33: =sum(H34:H52) -> 2381361 | I33: =sum(I34:I52) -> 0 | J33: =sum(J34:J52) -> 234575 | ... AH33: =sum(AH34:AH52) -> 7270528
A34: Electricidad | B34: =AH34/$AH$10 -> 0.004667561 | C34: 0 | D34: 0 | E34: 0 | F34: 0 | G34: 0 | H34: 0 | I34: 0 | J34: 0 | K34: 0 | L34: 0 | M34: 0 | N34: 0 | O34: 0 | P34: 0 | Q34: 0 | R34: 0 | S34: 194382 | T34: 0 | U34: 0 | V34: 0 | W34: 0 | X34: 0 | Y34: 0 | Z34: 0 | AA34: 0 | AB34: 0 | AC34: 0 | AD34: 0 | AE34: 0 | AF34: 0 | AG34: 0 | AH34: =SUM(C34:AG34) -> 194382
A35: Agua | B35: =AH35/$AH$10 -> 0.0015922563 | C35: 0 | D35: 0 | E35: 0 | F35: 0 | G35: 0 | H35: 0 | I35: 0 | J35: 0 | K35: 0 | L35: 0 | M35: 0 | N35: 0 | O35: 0 | P35: 0 | Q35: 0 | R35: 0 | S35: 66310 | T35: 0 | U35: 0 | V35: 0 | W35: 0 | X35: 0 | Y35: 0 | Z35: 0 | AA35: 0 | AB35: 0 | AC35: 0 | AD35: 0 | AE35: 0 | AF35: 0 | AG35: 0 | AH35: =SUM(C35:AG35) -> 66310
A36: Gas | B36: =AH36/$AH$10 -> 0.008989993 | C36: 0 | D36: 0 | E36: 0 | F36: 0 | G36: 0 | H36: 0 | I36: 0 | J36: 0 | K36: 0 | L36: 0 | M36: 0 | N36: 0 | O36: 0 | P36: 0 | Q36: 0 | R36: 0 | S36: 374391 | T36: 0 | U36: 0 | V36: 0 | W36: 0 | X36: 0 | Y36: 0 | Z36: 0 | AA36: 0 | AB36: 0 | AC36: 0 | AD36: 0 | AE36: 0 | AF36: 0 | AG36: 0 | AH36: =SUM(C36:AG36) -> 374391
A37: Restaurantpe | B37: =AH37/$AH$10 -> 0 | C37: 0 | D37: 0 | E37: 0 | F37: 0 | G37: 0 | H37: 0 | I37: 0 | J37: 0 | K37: 0 | L37: 0 | M37: 0 | N37: 0 | O37: 0 | P37: 0 | Q37: 0 | R37: 0 | S37: 0 | T37: 0 | U37: 0 | V37: 0 | W37: 0 | X37: 0 | Y37: 0 | Z37: 0 | AA37: 0 | AB37: 0 | AC37: 0 | AD37: 0 | AE37: 0 | AF37: 0 | AG37: 0 | AH37: =SUM(C37:AG37) -> 0
A38: Toteat | B38: =AH38/$AH$10 -> 0.0056326878 | C38: 0 | D38: 0 | E38: 0 | F38: 0 | G38: 0 | H38: 0 | I38: 0 | J38: =136614+97961 -> 234575 | K38: 0 | L38: 0 | M38: 0 | N38: 0 | O38: 0 | P38: 0 | Q38: 0 | R38: 0 | S38: 0 | T38: 0 | U38: 0 | V38: 0 | W38: 0 | X38: 0 | Y38: 0 | Z38: 0 | AA38: 0 | AB38: 0 | AC38: 0 | AD38: 0 | AE38: 0 | AF38: 0 | AG38: 0 | AH38: =SUM(C38:AG38) -> 234575
A39: Alarma | B39: =AH39/$AH$10 -> 0.0011458675 | C39: 0 | D39: 0 | E39: 0 | F39: 0 | G39: 0 | H39: 0 | I39: 0 | J39: 0 | K39: 47720 | L39: 0 | M39: 0 | N39: 0 | O39: 0 | P39: 0 | Q39: 0 | R39: 0 | S39: 0 | T39: 0 | U39: 0 | V39: 0 | W39: 0 | X39: 0 | Y39: 0 | Z39: 0 | AA39: 0 | AB39: 0 | AC39: 0 | AD39: 0 | AE39: 0 | AF39: 0 | AG39: 0 | AH39: =SUM(C39:AG39) -> 47720
A40: VTR | B40: =AH40/$AH$10 -> 0.00062724958 | C40: 0 | D40: 0 | E40: 0 | F40: 0 | G40: 0 | H40: 0 | I40: 0 | J40: 0 | K40: 0 | L40: 0 | M40: 0 | N40: 0 | O40: 11811 | P40: 0 | Q40: 0 | R40: 0 | S40: 14311 | T40: 0 | U40: 0 | V40: 0 | W40: 0 | X40: 0 | Y40: 0 | Z40: 0 | AA40: 0 | AB40: 0 | AC40: 0 | AD40: 0 | AE40: 0 | AF40: 0 | AG40: 0 | AH40: =SUM(C40:AG40) -> 26122
A41: Bodega | B41: =AH41/$AH$10 -> 0.0072036932 | C41: 0 | D41: 0 | E41: 0 | F41: 0 | G41: 0 | H41: 300000 | I41: 0 | J41: 0 | K41: 0 | L41: 0 | M41: 0 | N41: 0 | O41: 0 | P41: 0 | Q41: 0 | R41: 0 | S41: 0 | T41: 0 | U41: 0 | V41: 0 | W41: 0 | X41: 0 | Y41: 0 | Z41: 0 | AA41: 0 | AB41: 0 | AC41: 0 | AD41: 0 | AE41: 0 | AF41: 0 | AG41: 0 | AH41: =SUM(C41:AG41) -> 300000
A42: Arriendo | B42: =AH42/$AH$10 -> 0.043855148 | C42: 0 | D42: 0 | E42: 0 | F42: 0 | G42: 0 | H42: 1826361 | I42: 0 | J42: 0 | K42: 0 | L42: 0 | M42: 0 | N42: 0 | O42: 0 | P42: 0 | Q42: 0 | R42: 0 | S42: 0 | T42: 0 | U42: 0 | V42: 0 | W42: 0 | X42: 0 | Y42: 0 | Z42: 0 | AA42: 0 | AB42: 0 | AC42: 0 | AD42: 0 | AE42: 0 | AF42: 0 | AG42: 0 | AH42: =SUM(C42:AG42) -> 1826361
A43: Funmigacion | B43: =AH43/$AH$10 -> 0.0028298508 | C43: 0 | D43: 0 | E43: 0 | F43: 0 | G43: 0 | H43: 0 | I43: 0 | J43: 0 | K43: 0 | L43: 0 | M43: 0 | N43: 0 | O43: 0 | P43: 0 | Q43: 0 | R43: 0 | S43: 0 | T43: 0 | U43: 0 | V43: 117850 | W43: 0 | X43: 0 | Y43: 0 | Z43: 0 | AA43: 0 | AB43: 0 | AC43: 0 | AD43: 0 | AE43: 0 | AF43: 0 | AG43: 0 | AH43: =SUM(C43:AG43) -> 117850
A44: Aroclean | B44: =AH44/$AH$10 -> 0.0033135068 | C44: 0 | D44: 0 | E44: 0 | F44: 0 | G44: 0 | H44: 0 | I44: 0 | J44: 0 | K44: 68996 | L44: 0 | M44: 0 | N44: 0 | O44: 0 | P44: 0 | Q44: 0 | R44: 0 | S44: 0 | T44: 0 | U44: 0 | V44: 68996 | W44: 0 | X44: 0 | Y44: 0 | Z44: 0 | AA44: 0 | AB44: 0 | AC44: 0 | AD44: 0 | AH44: =SUM(C44:AG44) -> 137992
...

Sheet Marzo
C1: 46082 | D1: 46083 | E1: 46084 | F1: 46085 | G1: 46086 | H1: 46087 | I1: 46088 | J1: 46089 | K1: 46090 | L1: 46091 | M1: 46092 | N1: 46093 | O1: 46094 | P1: 46095 | Q1: 46096 | R1: 46097 | S1: 46098 | T1: 46099 | U1: 46100 | V1: 46101 | W1: 46102 | X1: 46103 | Y1: 46104 | Z1: 46105 | AA1: 46106 | AB1: 46107 | AC1: 46108 | AD1: 46109 | AE1: 46110 | AF1: 46111 | AG1: 46112 | AH1: Totales
A4: Ingresos
A5: Transbank | C5: =101972+558399+1912448 -> 2572819 | D5: =10402+235655+1074530 -> 1320587 | E5: =218017+30292 -> 248309 | F5: =36170+666573+667006+15943 -> 1385692 | G5: =439805+320141+61779+28796 -> 850521 | H5: =572819+95070+536572+29195 -> 1233656 | I5: =111004+957263+812195+209298 -> 2089760 | J5: =1542953+566171+43843+99344+17647 -> 2269958 | K5: =87089+1159007+161522+34742 -> 1442360 | L5: =30591+74469 -> 105060 | M5: =470324+632956+66185 -> 1169465 | N5: =725159+370053+26405 -> 1121617 | O5: =22419+916538+374056+75031 -> 1388044 | P5: =554234+19730+1082502+23117+28479 -> 1708062 | Q5: =45936+421095+1088033+158633 -> 1713697 | R5: =200383+684768+28700 -> 913851 | S5: =45230+23217+2872+S6 -> 71319 | T5: =514361+442837+36104+8868+38761 -> 1040931 | U5: =244245+639804+46155+35771 -> 965975 | V5: =11709+235237+61580+784927 -> 1093453 | W5: =712418+630939+46434+144796 -> 1534587 | X5: =604572+969415+101938 -> 1675925 | Y5: =12271+837071+440924+50519 -> 1340785 | Z5: 19950 | AA5: =16540+379476+578204 -> 974220 | AB5: =464555+32982+292650+54841 -> 845028 | AC5: =228610+939251+23317+36060+25807 -> 1253045 | AD5: =731697+414855+113593 -> 1260145 | AE5: =54306+119073+651539+1448251+53011 -> 2326180 | AF5: =166104+803143 -> 969247 | AG5: =16671+54305+278841 -> 349817 | AH5: =SUM(C5:AG5) -> 37254065
A6: Transferencias | C6: 0 | D6: 0 | E6: 0 | F6: 25900 | G6: 26220 | H6: 0 | I6: 1800 | J6: 0 | K6: 0 | L6: 0 | M6: 25900 | N6: 0 | O6: 198650 | P6: 14700 | Q6: 0 | R6: 0 | S6: 0 | T6: 0 | U6: 0 | V6: 0 | W6: 0 | X6: 0 | Y6: 0 | Z6: 0 | AA6: 0 | AB6: 67200 | AC6: 0 | AD6: 12900 | AE6: 42000 | AF6: 16240 | AG6: 0 | AH6: =SUM(C6:AG6) -> 431510
A7: Efectivo | C7: 0 | D7: 0 | E7: 0 | F7: 0 | G7: 0 | H7: 0 | I7: 0 | J7: 0 | K7: 0 | L7: 0 | M7: 0 | N7: 0 | O7: 0 | P7: 0 | Q7: 0 | R7: 0 | S7: 0 | T7: 0 | U7: 0 | V7: 0 | W7: 0 | X7: 0 | Y7: 0 | Z7: 0 | AA7: 0 | AB7: 0 | AC7: 0 | AD7: 0 | AE7: 0 | AF7: 0 | AG7: 200000 | AH7: =SUM(C7:AG7) -> 200000
A8: Uber | C8: 0 | D8: 0 | E8: =285025+529384 -> 814409 | F8: 0 | G8: 0 | H8: 0 | I8: 0 | J8: 0 | K8: 0 | L8: =444793+162633 -> 607426 | M8: 0 | N8: 0 | O8: 0 | P8: 0 | Q8: 0 | R8: 0 | S8: =496444+194626 -> 691070 | T8: 0 | U8: 0 | V8: 0 | W8: 0 | X8: 0 | Y8: 0 | Z8: =562344+259622 -> 821966 | AA8: 0 | AB8: 0 | AC8: 0 | AD8: 0 | AE8: 0 | AF8: 0 | AG8: 0 | AH8: =SUM(C8:AG8) -> 2934871
A9: Total bruto | C9: =SUM(C5:C8) -> 2572819 | D9: =SUM(D5:D8) -> 1320587 | E9: =SUM(E5:E8) -> 1062718 | F9: =SUM(F5:F8) -> 1411592 | G9: =SUM(G5:G8) -> 876741 | H9: =SUM(H5:H8) -> 1233656 | I9: =SUM(I5:I8) -> 2091560 | J9: =SUM(J5:J8) -> 2269958 | ... AH9: =SUM(AH5:AH8) -> 40820446
A10: Total neto | AH10: =AH9-AH82 -> 36939460
A12: Materia prima | B12: =AH12/$AH$10 -> 0.33387759 | C12: =sum(C13:C30) -> 7000 | D12: =sum(D13:D30) -> 30300 | E12: =sum(E13:E30) -> 1156221 | F12: =sum(F13:F30) -> 1240950 | G12: =sum(G13:G30) -> 84000 | H12: =sum(H13:H30) -> 0 | I12: =sum(I13:I30) -> 175212 | J12: =sum(J13:J30) -> 15020 | ... AG12: =sum(AG13:AG30) -> 1609185 | AH12: =sum(AH13:AH31) -> 12333258
A13: MP | B13: =AH13/$AH$10 -> 0.057693047 | C13: 0 | D13: =12800+17500 -> 30300 | E13: =30000+84000+60000 -> 174000 | F13: 0 | G13: 84000 | H13: 0 | I13: =36000+69001+15280 -> 120281 | J13: 15020 | K13: 0 | L13: 15420 | M13: 0 | N13: 10590 | O13: =22970+233835+26490 -> 283295 | P13: =15600+6000 -> 21600 | Q13: 12220 | R13: =84000+7530 -> 91530 | S13: 55770 | T13: =20841+96250 -> 117091 | U13: 0 | V13: 86190 | W13: 0 | X13: 7900 | Y13: 0 | Z13: 238000 | AA13: =51338+238000 -> 289338 | AB13: =65530+20610 -> 86140 | AC13: =84500+94000+71400 -> 249900 | AD13: 63975 | AE13: 0 | AF13: =15800+26840 -> 42640 | AG13: 35950 | AH13: =SUM(C13:AG13) -> 2131150
A14: Arroz | B14: =AH14/$AH$10 -> 0.011776025 | C14: 0 | D14: 0 | E14: 87000 | F14: 0 | G14: 0 | H14: 0 | I14: 0 | J14: 0 | K14: 0 | L14: 116000 | M14: 0 | N14: 0 | O14: 0 | P14: 0 | Q14: 0 | R14: 0 | S14: 0 | T14: 116000 | U14: 0 | V14: 0 | W14: 0 | X14: 0 | Y14: 0 | Z14: 0 | AA14: 0 | AB14: 0 | AC14: 0 | AD14: 0 | AE14: 0 | AF14: 0 | AG14: 116000 | AH14: =SUM(C14:AG14) -> 435000
A15: Hod Food | B15: =AH15/$AH$10 -> 0.077739848 | C15: 0 | D15: 0 | E15: 0 | F15: 757851 | G15: 0 | H15: 0 | I15: 0 | J15: 0 | K15: 0 | L15: 448404 | M15: 0 | N15: 0 | O15: 0 | P15: 0 | Q15: 0 | R15: 0 | S15: 0 | T15: 350990 | U15: 0 | V15: 0 | W15: 0 | X15: 0 | Y15: 0 | Z15: 0 | AA15: 834557 | AB15: 0 | AC15: 0 | AD15: 0 | AE15: 0 | AF15: 0 | AG15: 479866 | AH15: =SUM(C15:AG15) -> 2871668
A16: Seitan | B16: =AH16/$AH$10 -> 0.008337209 | C16: 0 | D16: 0 | E16: 153986 | F16: 0 | G16: 0 | H16: 0 | I16: 0 | J16: 0 | K16: 0 | L16: 0 | M16: 0 | N16: 0 | O16: 0 | P16: 153986 | Q16: 0 | R16: 0 | S16: 0 | T16: 0 | U16: 0 | V16: 0 | W16: 0 | X16: 0 | Y16: 0 | Z16: 0 | AA16: 0 | AB16: 0 | AC16: 0 | AD16: 0 | AE16: 0 | AF16: 0 | AG16: 0 | AH16: =SUM(C16:AG16) -> 307972
A17: Palta | B17: =AH17/$AH$10 -> 0.037308044 | C17: 0 | D17: 0 | E17: 0 | F17: 0 | G17: 0 | H17: 0 | I17: 0 | J17: 0 | K17: 0 | L17: 486115 | M17: 0 | N17: 0 | O17: 0 | P17: 0 | Q17: 0 | R17: 0 | S17: 0 | T17: 0 | U17: 447559 | V17: 0 | W17: 0 | X17: 0 | Y17: 0 | Z17: 0 | AA17: 0 | AB17: 0 | AC17: 0 | AD17: 0 | AE17: 0 | AF17: 0 | AG17: 444465 | AH17: =SUM(C17:AG17) -> 1378139
A18: Carivo | B18: =AH18/$AH$10 -> 0.065381844 | C18: 0 | D18: 0 | E18: 459220 | F18: 0 | G18: 0 | H18: 0 | I18: 0 | J18: 0 | K18: 0 | L18: 597150 | M18: 0 | N18: 0 | O18: 0 | P18: 0 | Q18: 0 | R18: 0 | S18: 524350 | T18: 0 | U18: 0 | V18: 0 | W18: 0 | X18: 0 | Y18: 0 | Z18: 427210 | AA18: 0 | AB18: 0 | AC18: 0 | AD18: 0 | AE18: 0 | AF18: 0 | AG18: 407240 | AH18: =SUM(C18:AG18) -> 2415170
A19: Shen | B19: =AH19/$AH$10 -> 0.010569321 | C19: 0 | D19: 0 | E19: 136850 | F19: 0 | G19: 0 | H19: 0 | I19: 0 | J19: 0 | K19: 0 | L19: 0 | M19: 0 | N19: 0 | O19: 0 | P19: 0 | Q19: 0 | R19: 0 | S19: 169575 | T19: 0 | U19: 0 | V19: 0 | W19: 0 | X19: 0 | Y19: 0 | Z19: 0 | AA19: 84000 | AB19: 0 | AC19: 0 | AD19: 0 | AE19: 0 | AF19: 0 | AG19: 0 | AH19: =SUM(C19:AG19) -> 390425
A20: Mozzen | B20: =AH20/$AH$10 -> 0.0061652769 | C20: 0 | D20: 0 | E20: 0 | F20: 227742 | G20: 0 | H20: 0 | I20: 0 | J20: 0 | K20: 0 | L20: 0 | M20: 0 | N20: 0 | O20: 0 | P20: 0 | Q20: 0 | R20: 0 | S20: 0 | T20: 0 | U20: 0 | V20: 0 | W20: 0 | X20: 0 | Y20: 0 | Z20: 0 | AA20: 0 | AB20: 0 | AC20: 0 | AD20: 0 | AE20: 0 | AF20: 0 | AG20: 0 | AH20: =SUM(C20:AG20) -> 227742
A21: Café y Té | B21: =AH21/$AH$10 -> 0 | C21: 0 | D21: 0 | E21: 0 | F21: 0 | G21: 0 | H21: 0 | I21: 0 | J21: 0 | K21: 0 | L21: 0 | M21: 0 | N21: 0 | O21: 0 | P21: 0 | Q21: 0 | R21: 0 | S21: 0 | T21: 0 | U21: 0 | V21: 0 | W21: 0 | X21: 0 | Y21: 0 | Z21: 0 | AA21: 0 | AB21: 0 | AC21: 0 | AD21: 0 | AE21: 0 | AF21: 0 | AG21: 0 | AH21: =SUM(C21:AG21) -> 0
A22: Leche de soya | B22: =AH22/$AH$10 -> 0.0036531666 | C22: 0 | D22: 0 | E22: 0 | F22: 0 | G22: 0 | H22: 0 | I22: 0 | J22: 0 | K22: 0 | L22: 0 | M22: 0 | N22: 0 | O22: 0 | P22: 0 | Q22: 0 | R22: 0 | S22: 134946 | T22: 0 | U22: 0 | V22: 0 | W22: 0 | X22: 0 | Y22: 0 | Z22: 0 | AA22: 0 | AB22: 0 | AC22: 0 | AD22: 0 | AE22: 0 | AF22: 0 | AG22: 0 | AH22: =SUM(C22:AG22) -> 134946
A23: Bebestibles | B23: =AH23/$AH$10 -> 0.0049664776 | C23: 0 | D23: 0 | E23: =19501 -> 19501 | F23: 0 | G23: 0 | H23: 0 | I23: 0 | J23: 0 | K23: 0 | L23: 0 | M23: 19501 | N23: 0 | O23: 0 | P23: 0 | Q23: 0 | R23: 0 | S23: 0 | T23: 75047 | U23: 0 | V23: 0 | W23: 23205 | X23: 0 | Y23: 0 | Z23: 23000 | AA23: 0 | AB23: 0 | AC23: 23205 | AD23: 0 | AE23: 0 | AF23: 0 | AG23: 0 | AH23: =SUM(C23:AG23) -> 183459
A24: Brugga | B24: =AH24/$AH$10 -> 0.01275709 | C24: 0 | D24: 0 | E24: 125664 | F24: 0 | G24: 0 | H24: 0 | I24: 0 | J24: 0 | K24: 0 | L24: 0 | M24: 0 | N24: 0 | O24: 125664 | P24: 0 | Q24: 0 | R24: 0 | S24: 0 | T24: 0 | U24: 94248 | V24: 0 | W24: 0 | X24: 0 | Y24: 0 | Z24: 0 | AA24: 0 | AB24: 0 | AC24: 0 | AD24: 0 | AE24: 0 | AF24: 0 | AG24: 125664 | AH24: =SUM(C24:AG24) -> 471240
A25: Colación | B25: =AH25/$AH$10 -> 0.0065281951 | C25: 7000 | D25: 0 | E25: 0 | F25: 0 | G25: 0 | H25: 0 | I25: 54931 | J25: 0 | K25: 12320 | L25: 0 | M25: 0 | N25: 46509 | O25: 0 | P25: 0 | Q25: 10400 | R25: 6780 | S25: 0 | T25: 0 | U25: 0 | V25: 29008 | W25: 0 | X25: 0 | Y25: 0 | Z25: 0 | AA25: 0 | AB25: 9490 | AC25: 56810 | AD25: 0 | AE25: 7900 | AF25: 0 | AG25: 0 | AH25: =SUM(C25:AG25) -> 241148
A26: Empaques y desechables | B26: =AH26/$AH$10 -> 0.013309317 | C26: 0 | D26: 0 | E26: 0 | F26: 137957 | G26: 0 | H26: 0 | I26: 0 | J26: 0 | K26: 0 | L26: 0 | M26: 0 | N26: 160168 | O26: 0 | P26: 0 | Q26: 0 | R26: 0 | S26: 10500 | T26: 0 | U26: 0 | V26: 0 | W26: 0 | X26: 0 | Y26: 0 | Z26: 0 | AA26: 6000 | AB26: 154914 | AC26: 22100 | AD26: 0 | AE26: 0 | AF26: 0 | AG26: 0 | AH26: =SUM(C26:AG26) -> 491639
A27: Soyas sachet | B27: =AH27/$AH$10 -> 0.0024363377 | C27: 0 | D27: 0 | E27: 0 | F27: 0 | G27: 0 | H27: 0 | I27: 0 | J27: 0 | K27: 0 | L27: 0 | M27: 0 | N27: 0 | O27: 0 | P27: 0 | Q27: 0 | R27: 0 | S27: 89997 | T27: 0 | U27: 0 | V27: 0 | W27: 0 | X27: 0 | Y27: 0 | Z27: 0 | AA27: 0 | AB27: 0 | AC27: 0 | AD27: 0 | AE27: 0 | AF27: 0 | AG27: 0 | AH27: =SUM(C27:AG27) -> 89997
A28: Servilletas | B28: =AH28/$AH$10 -> 0 | C28: 0 | D28: 0 | E28: 0 | F28: 0 | G28: 0 | H28: 0 | I28: 0 | J28: 0 | K28: 0 | L28: 0 | M28: 0 | N28: 0 | O28: 0 | P28: 0 | Q28: 0 | R28: 0 | S28: 0 | T28: 0 | U28: 0 | V28: 0 | W28: 0 | X28: 0 | Y28: 0 | Z28: 0 | AA28: 0 | AB28: 0 | AC28: 0 | AD28: 0 | AE28: 0 | AF28: 0 | AG28: 0 | AH28: =SUM(C28:AG28) -> 0
A29: Limpieza e higiene | B29: =AH29/$AH$10 -> 0.0014410064 | C29: 0 | D29: 0 | E29: 0 | F29: 0 | G29: 0 | H29: 0 | I29: 0 | J29: 0 | K29: 0 | L29: 0 | M29: 0 | N29: 0 | O29: 0 | P29: 0 | Q29: 0 | R29: 0 | S29: 0 | T29: 0 | U29: 0 | V29: 0 | W29: 0 | X29: 0 | Y29: 53230 | Z29: 0 | AA29: 0 | AB29: 0 | AC29: 0 | AD29: 0 | AE29: 0 | AF29: 0 | AG29: 0 | AH29: =SUM(C29:AG29) -> 53230
A30: Postres | B30: =AH30/$AH$10 -> 0.013815389 | C30: 0 | D30: 0 | E30: 0 | F30: 117400 | G30: 0 | H30: 0 | I30: 0 | J30: 0 | K30: 0 | L30: 0 | M30: 0 | N30: 0 | O30: 0 | P30: 241218 | Q30: 0 | R30: 75000 | S30: 0 | T30: 76715 | U30: 0 | V30: 0 | W30: 0 | X30: 0 | Y30: 0 | Z30: 0 | AA30: 0 | AB30: 0 | AC30: 0 | AD30: 0 | AE30: 0 | AF30: 0 | AG30: 0 | AH30: =SUM(C30:AG30) -> 510333
AH31: =SUM(C31:AG31) -> 0
A32: Gastos FV | B32: =AH32/$AH$10 -> 0.20771281 | C32: =sum(C33+C53+C63) -> 0 | D32: =sum(D33+D53+D63) -> 0 | E32: =sum(E33+E53+E63) -> 58245 | F32: =sum(F33+F53+F63) -> 223822 | G32: =sum(G33+G53+G63) -> 9401 | H32: =sum(H33+H53+H63) -> 1864570 | I32: =sum(I33+I53+I63) -> 108969 | J32: =sum(J33+J53+J63) -> 0 | ... AH32: =sum(AH33+AH53+AH63) -> 7672799
A33: Operaciones | B33: =AH33/$AH$10 -> 0.17493182 | C33: =sum(C34:C52) -> 0 | D33: =sum(D34:D52) -> 0 | E33: =sum(E34:E52) -> 0 | F33: =sum(F34:F52) -> 223822 | G33: =sum(G34:G52) -> 0 | H33: =sum(H34:H52) -> 1860620 | I33: =sum(I34:I52) -> 0 | J33: =sum(J34:J52) -> 0 | ... AH33: =sum(AH34:AH52) -> 6461887
A34: Electricidad | B34: =AH34/$AH$10 -> 0.0056157562 | C34: 0 | D34: 0 | E34: 0 | F34: 0 | G34: 0 | H34: 0 | I34: 0 | J34: 0 | K34: 0 | L34: 0 | M34: 0 | N34: 0 | O34: 0 | P34: 0 | Q34: 0 | R34: 0 | S34: 194080 | T34: 0 | U34: 0 | V34: 0 | W34: 0 | X34: 0 | Y34: 0 | Z34: 0 | AA34: 0 | AB34: 0 | AC34: 13363 | AD34: 0 | AE34: 0 | AF34: 0 | AG34: 0 | AH34: =SUM(C34:AG34) -> 207443
A35: Agua | B35: =AH35/$AH$10 -> 0.002995171 | C35: 0 | D35: 0 | E35: 0 | F35: 0 | G35: 0 | H35: 0 | I35: 0 | J35: 0 | K35: 0 | L35: 0 | M35: 0 | N35: 0 | O35: 0 | P35: 0 | Q35: 0 | R35: 0 | S35: 110640 | T35: 0 | U35: 0 | V35: 0 | W35: 0 | X35: 0 | Y35: 0 | Z35: 0 | AA35: 0 | AB35: 0 | AC35: 0 | AD35: 0 | AE35: 0 | AF35: 0 | AG35: 0 | AH35: =SUM(C35:AG35) -> 110640
A36: Gas | B36: =AH36/$AH$10 -> 0.01067942 | C36: 0 | D36: 0 | E36: 0 | F36: 0 | G36: 0 | H36: 0 | I36: 0 | J36: 0 | K36: 0 | L36: 0 | M36: 0 | N36: 0 | O36: 0 | P36: 0 | Q36: 0 | R36: 0 | S36: 394492 | T36: 0 | U36: 0 | V36: 0 | W36: 0 | X36: 0 | Y36: 0 | Z36: 0 | AA36: 0 | AB36: 0 | AC36: 0 | AD36: 0 | AE36: 0 | AF36: 0 | AG36: 0 | AH36: =SUM(C36:AG36) -> 394492
A37: Restaurantpe | B37: =AH37/$AH$10 -> 0 | C37: 0 | D37: 0 | E37: 0 | F37: 0 | G37: 0 | H37: 0 | I37: 0 | J37: 0 | K37: 0 | L37: 0 | M37: 0 | N37: 0 | O37: 0 | P37: 0 | Q37: 0 | R37: 0 | S37: 0 | T37: 0 | U37: 0 | V37: 0 | W37: 0 | X37: 0 | Y37: 0 | Z37: 0 | AA37: 0 | AB37: 0 | AC37: 0 | AD37: 0 | AE37: 0 | AF37: 0 | AG37: 0 | AH37: =SUM(C37:AG37) -> 0
A38: Toteat | B38: =AH38/$AH$10 -> 0.0060591573 | C38: 0 | D38: 0 | E38: 0 | F38: =87812+136010 -> 223822 | G38: 0 | H38: 0 | I38: 0 | J38: 0 | K38: 0 | L38: 0 | M38: 0 | N38: 0 | O38: 0 | P38: 0 | Q38: 0 | R38: 0 | S38: 0 | T38: 0 | U38: 0 | V38: 0 | W38: 0 | X38: 0 | Y38: 0 | Z38: 0 | AA38: 0 | AB38: 0 | AC38: 0 | AD38: 0 | AE38: 0 | AF38: 0 | AG38: 0 | AH38: =SUM(C38:AG38) -> 223822
A39: Alarma | B39: =AH39/$AH$10 -> 0.0012948484 | C39: 0 | D39: 0 | E39: 0 | F39: 0 | G39: 0 | H39: 0 | I39: 0 | J39: 0 | K39: 0 | L39: 0 | M39: 0 | N39: 0 | O39: 0 | P39: 0 | Q39: 0 | R39: 0 | S39: 47831 | T39: 0 | U39: 0 | V39: 0 | W39: 0 | X39: 0 | Y39: 0 | Z39: 0 | AA39: 0 | AB39: 0 | AC39: 0 | AD39: 0 | AE39: 0 | AF39: 0 | AG39: 0 | AH39: =SUM(C39:AG39) -> 47831
A40: VTR | B40: =AH40/$AH$10 -> 0.00031973938 | C40: 0 | D40: 0 | E40: 0 | F40: 0 | G40: 0 | H40: 0 | I40: 0 | J40: 0 | K40: 0 | L40: 0 | M40: 0 | N40: 0 | O40: 0 | P40: 0 | Q40: 0 | R40: 0 | S40: 11811 | T40: 0 | U40: 0 | V40: 0 | W40: 0 | X40: 0 | Y40: 0 | Z40: 0 | AA40: 0 | AB40: 0 | AC40: 0 | AD40: 0 | AE40: 0 | AF40: 0 | AG40: 0 | AH40: =SUM(C40:AG40) -> 11811
A41: Bodega | B41: =AH41/$AH$10 -> 0.0094749625 | C41: 0 | D41: 0 | E41: 0 | F41: 0 | G41: 0 | H41: 0 | I41: 0 | J41: 0 | K41: 0 | L41: 0 | M41: 0 | N41: 0 | O41: 0 | P41: 0 | Q41: 0 | R41: 0 | S41: 0 | T41: 0 | U41: 0 | V41: 0 | W41: 0 | X41: 0 | Y41: 0 | Z41: 0 | AA41: 0 | AB41: 0 | AC41: 0 | AD41: 350000 | AE41: 0 | AF41: 0 | AG41: 0 | AH41: =SUM(C41:AG41) -> 350000
A42: Arriendo | B42: =AH42/$AH$10 -> 0.049557303 | C42: 0 | D42: 0 | E42: 0 | F42: 0 | G42: 0 | H42: 1830620 | I42: 0 | J42: 0 | K42: 0 | L42: 0 | M42: 0 | N42: 0 | O42: 0 | P42: 0 | Q42: 0 | R42: 0 | S42: 0 | T42: 0 | U42: 0 | V42: 0 | W42: 0 | X42: 0 | Y42: 0 | Z42: 0 | AA42: 0 | AB42: 0 | AC42: 0 | AD42: 0 | AE42: 0 | AF42: 0 | AG42: 0 | AH42: =SUM(C42:AG42) -> 1830620
A43: Funmigacion | B43: =AH43/$AH$10 -> 0.0027071322 | C43: 0 | D43: 0 | E43: 0 | F43: 0 | G43: 0 | H43: 0 | I43: 0 | J43: 0 | K43: 0 | L43: 0 | M43: 0 | N43: 0 | O43: 0 | P43: 0 | Q43: 0 | R43: 0 | S43: 0 | T43: 0 | U43: 0 | V43: 0 | W43: 0 | X43: 0 | Y43: 0 | Z43: 0 | AA43: 0 | AB43: 0 | AC43: 0 | AD43: 0 | AE43: 0 | AF43: 0 | AG43: 100000 | AH43: =SUM(C43:AG43) -> 100000
...

Sheet Abril
C1: 46113 | D1: 46114 | E1: 46115 | F1: 46116 | G1: 46117 | H1: 46118 | I1: 46119 | J1: 46120 | K1: 46121 | L1: 46122 | M1: 46123 | N1: 46124 | O1: 46125 | P1: 46126 | Q1: 46127 | R1: 46128 | S1: 46129 | T1: 46130 | U1: 46131 | V1: 46132 | W1: 46133 | X1: 46134 | Y1: 46135 | Z1: 46136 | AA1: 46137 | AB1: 46138 | AC1: 46139 | AD1: 46140 | AE1: 46141 | AF1: 46142 | AH1: Totales
A4: Ingresos
A5: Transbank | C5: =667957+79894+912033+8131+106219 -> 1774234 | D5: =870428+489261+37666+177465 -> 1574820 | E5: =677368+717856+225891+66960+8071 -> 1696146 | F5: =442216+1285065+46633 -> 1773914 | G5: =70050+356223+1336911+97849 -> 1861033 | H5: =1250181+271029 -> 1521210 | I5: =278271+38941+3951 -> 321163 | J5: =448991+400286+30010+16540 -> 895827 | K5: =695233+316979+154031 -> 1166243 | L5: =1212830+35505+702249+39857+39833+11091 -> 2041365 | M5: =28598+553457+575438+209192+44839 -> 1411524 | N5: =469020+74333+1223646+53906 -> 1820905 | O5: =201577+537734+6268 -> 745579 | P5: =145167+44517+14857 -> 204541 | Q5: =24289+496073+537042+13850 -> 1071254 | R5: =615469+288051+56897+5273 -> 965690 | S5: =436873+248785+45054+20606+50319 -> 801637 | T5: =838581+333876+70946+39857 -> 1283260 | U5: =1079633+553715+74732+85693 -> 1793773 | V5: =1136070+360409 -> 1496479 | W5: =112370+24288+19550 -> 156208 | X5: =366602+589928+13850 -> 970380 | Y5: =364875+36569+748326+68979 -> 1218749 | Z5: =883235+1011032+184880+17795+88085 -> 2185027 | AA5: =569436+14425+553991+69351+23318 -> 1230521 | AB5: =135713+1863773+31587+354162 -> 2385235 | AC5: =137009+999668+34576 -> 1171253 | AD5: =219722+66434 -> 286156 | AE5: =515463+115297+25807+43412 -> 699979 | AF5: =469886+543452+7807+109110 -> 1130255 | AG5: 0 | AH5: =SUM(C5:AG5) -> 37654360
A6: Transferencias | C6: 0 | D6: 0 | E6: 9020 | F6: 0 | G6: 0 | H6: 0 | I6: 0 | J6: 0 | K6: 0 | L6: 0 | M6: 0 | N6: 0 | O6: 0 | P6: 55000 | Q6: 25900 | R6: 0 | S6: 0 | T6: 0 | U6: 21455 | V6: 0 | W6: 0 | X6: 0 | Y6: 30240 | Z6: 1300 | AA6: 0 | AB6: 0 | AC6: 0 | AD6: 0 | AE6: 18950 | AF6: 0 | AG6: 0 | AH6: =SUM(C6:AG6) -> 161865
A7: Efectivo | C7: 0 | D7: 0 | E7: 0 | F7: 0 | G7: 0 | H7: 0 | I7: 0 | J7: 0 | K7: 0 | L7: 0 | M7: 0 | N7: 0 | O7: 0 | P7: 0 | Q7: 0 | R7: 0 | S7: 0 | T7: 0 | U7: 0 | V7: 0 | W7: 0 | X7: 0 | Y7: 0 | Z7: 0 | AA7: 0 | AB7: 0 | AC7: 0 | AD7: 200000 | AE7: 0 | AF7: 0 | AG7: 0 | AH7: =SUM(C7:AG7) -> 200000
A8: Uber | C8: 0 | D8: 0 | E8: 0 | F8: 0 | G8: 0 | H8: 0 | I8: 0 | J8: =503331+147765 -> 651096 | K8: 0 | L8: 0 | M8: 0 | N8: 0 | O8: 0 | P8: =295935+369316 -> 665251 | Q8: 0 | R8: 0 | S8: 0 | T8: 0 | U8: 0 | V8: 0 | W8: =426984+227006 -> 653990 | X8: 0 | Y8: 0 | Z8: 0 | AA8: 0 | AB8: 0 | AC8: 0 | AD8: =113291+558587 -> 671878 | AE8: 0 | AF8: 0 | AG8: 0 | AH8: =SUM(C8:AG8) -> 2642215
A9: Total bruto | C9: =SUM(C5:C8) -> 1774234 | D9: =SUM(D5:D8) -> 1574820 | E9: =SUM(E5:E8) -> 1705166 | F9: =SUM(F5:F8) -> 1773914 | G9: =SUM(G5:G8) -> 1861033 | H9: =SUM(H5:H8) -> 1521210 | I9: =SUM(I5:I8) -> 321163 | J9: =SUM(J5:J8) -> 1546923 | ... AH9: =SUM(AH5:AH8) -> 40658440
A10: Total neto | AH10: =AH9-AH83 -> 36439992
A12: Materia prima | B12: =AH12/$AH$10 -> 0.31195838 | C12: =sum(C13:C31) -> 655705 | D12: =sum(D13:D31) -> 92743 | E12: =sum(E13:E31) -> 71690 | F12: =sum(F13:F31) -> 56351 | G12: =sum(G15:G31) -> 12500 | H12: =sum(H13:H31) -> 500890 | I12: =sum(I13:I31) -> 1184070 | J12: =sum(J13:J31) -> 571936 | K12: =sum(K13:K31) -> 680475 | L12: =sum(L13:L31) -> 179150 | M12: =sum(M13:M31) -> 14380 | N12: =sum(N13:N31) -> 0 | O12: =sum(O13:O31) -> 330721 | ... AH12: =sum(AH13:AH31) -> 11367761
A13: MP | B13: =AH13/$AH$10 -> 0.02472989 | C13: =84000+50000 -> 134000 | D13: 50000 | E13: 59490 | F13: 0 | G13: 0 | H13: 62490 | I13: 0 | J13: 84000 | K13: 5200 | L13: 0 | M13: 14380 | N13: 0 | O13: 72470 | P13: 0 | Q13: 0 | R13: 0 | S13: 65000 | T13: 0 | U13: 0 | V13: 0 | W13: =95287+13990 -> 109277 | X13: 0 | Y13: 56490 | Z13: =41960+71000 -> 112960 | AA13: =10000+7800 -> 17800 | AB13: 0 | AC13: 0 | AD13: 0 | AE13: 84000+55000 | AF13: =37600+20000 -> 57600 | AG13: 0 | AH13: =SUM(C13:AG13) -> 901157
A14: Arroz | B14: =AH14/$AH$10 -> 0.013084525 | C14: 0 | D14: 0 | E14: 0 | F14: 0 | G14: 0 | H14: 0 | I14: 119200 | J14: 0 | K14: 0 | L14: 0 | M14: 0 | N14: 0 | O14: 0 | P14: 0 | Q14: 119200 | R14: 0 | S14: 0 | T14: 0 | U14: 0 | V14: 0 | W14: 0 | X14: 119200 | Y14: 0 | Z14: 0 | AA14: 0 | AB14: 0 | AC14: 0 | AD14: 0 | AE14: 119200 | AF14: 0 | AG14: 0 | AH14: =SUM(C14:AG14) -> 476800
A15: Hod Food | B15: =AH15/$AH$10 -> 0.067389312 | C15: 0 | D15: 0 | E15: 0 | F15: 0 | G15: 0 | H15: 0 | I15: 672333 | J15: 0 | K15: 0 | L15: 0 | M15: 0 | N15: 0 | O15: 0 | P15: 599256 | Q15: 0 | R15: 0 | S15: 0 | T15: 0 | U15: 0 | V15: 0 | W15: 399007 | X15: 0 | Y15: 0 | Z15: 0 | AA15: 0 | AB15: 0 | AC15: 0 | AD15: 577753 | AE15: 0 | AF15: 207317 | AG15: 0 | AH15: =SUM(C15:AG15) -> 2455666
A16: Seitan | B16: =AH16/$AH$10 -> 0.0084514837 | C16: 0 | D16: 0 | E16: 0 | F16: 0 | G16: 0 | H16: 0 | I16: 153986 | J16: 0 | K16: 0 | L16: 0 | M16: 0 | N16: 0 | O16: 0 | P16: 0 | Q16: 0 | R16: 0 | S16: 0 | T16: 0 | U16: 0 | V16: 0 | W16: 0 | X16: 0 | Y16: 0 | Z16: 0 | AA16: 0 | AB16: 0 | AC16: 0 | AD16: 0 | AE16: 0 | AF16: 153986 | AG16: 0 | AH16: =SUM(C16:AG16) -> 307972
A17: Palta | B17: =AH17/$AH$10 -> 0.036284558 | C17: 0 | D17: 0 | E17: 0 | F17: 0 | G17: 0 | H17: 428400 | I17: 0 | J17: 0 | K17: 0 | L17: 0 | M17: 0 | N17: 0 | O17: 0 | P17: 0 | Q17: 0 | R17: 401625 | S17: 0 | T17: 0 | U17: 156604 | V17: 0 | W17: 0 | X17: 0 | Y17: 0 | Z17: 335580 | AA17: 0 | AB17: 0 | AC17: 0 | AD17: 0 | AE17: 0 | AF17: 0 | AG17: 0 | AH17: =SUM(C17:AG17) -> 1322209
A18: Champiñon | B18: =AH18/$AH$10 -> 0.0073476965 | C18: 0 | D18: 0 | E18: 0 | F18: 0 | G18: 0 | H18: 0 | I18: 0 | J18: 0 | K18: 0 | L18: 0 | M18: 0 | N18: 0 | O18: 0 | P18: 0 | Q18: 0 | R18: 0 | S18: 0 | T18: 0 | U18: 0 | V18: 0 | W18: 0 | X18: 267750 | Y18: 0 | Z18: 0 | AA18: 0 | AB18: 0 | AC18: 0 | AD18: 0 | AE18: 0 | AF18: 0 | AG18: 0 | AH18: =SUM(C18:AG18) -> 267750
A19: Verduras | B19: =AH19/$AH$10 -> 0.066945404 | C19: 139825 | D19: 0 | E19: 0 | F19: 0 | G19: 0 | H19: 0 | I19: 0 | J19: 160650 | K19: 628405 | L19: 0 | M19: 0 | N19: 0 | O19: 0 | P19: 0 | Q19: 608450 | R19: 0 | S19: 0 | T19: 0 | U19: 0 | V19: 0 | W19: 413400 | X19: 0 | Y19: 0 | Z19: 0 | AA19: 0 | AB19: 0 | AC19: 0 | AD19: 0 | AE19: 488760 | AF19: 0 | AG19: 0 | AH19: =SUM(C19:AG19) -> 2439490
A20: shen | B20: =AH20/$AH$10 -> 0.017248357 | C20: 169575 | D20: 0 | E20: 0 | F20: 0 | G20: 0 | H20: 0 | I20: 0 | J20: 0 | K20: 0 | L20: 98770 | M20: 0 | N20: 0 | O20: 0 | P20: 0 | Q20: 0 | R20: 0 | S20: 101150 | T20: 0 | U20: 0 | V20: 84000 | W20: 0 | X20: 0 | Y20: 84000 | Z20: 0 | AA20: 0 | AB20: 0 | AC20: 0 | AD20: 0 | AE20: 91035 | AF20: 0 | AG20: 0 | AH20: =SUM(C20:AG20) -> 628530
A21: Mozzen | B21: =AH21/$AH$10 -> 0.0077745077 | C21: 0 | D21: 0 | E21: 0 | F21: 0 | G21: 0 | H21: 0 | I21: 0 | J21: 283303 | K21: 0 | L21: 0 | M21: 0 | N21: 0 | O21: 0 | P21: 0 | Q21: 0 | R21: 0 | S21: 0 | T21: 0 | U21: 0 | V21: 0 | W21: 0 | X21: 0 | Y21: 0 | Z21: 0 | AA21: 0 | AB21: 0 | AC21: 0 | AD21: 0 | AE21: 0 | AF21: 0 | AG21: 0 | AH21: =SUM(C21:AG21) -> 283303
A22: Café y Té | B22: =AH22/$AH$10 -> 0 | C22: 0 | D22: 0 | E22: 0 | F22: 0 | G22: 0 | H22: 0 | I22: 0 | J22: 0 | K22: 0 | L22: 0 | M22: 0 | N22: 0 | O22: 0 | P22: 0 | Q22: 0 | R22: 0 | S22: 0 | T22: 0 | U22: 0 | V22: 0 | W22: 0 | X22: 0 | Y22: 0 | Z22: 0 | AA22: 0 | AB22: 0 | AC22: 0 | AD22: 0 | AE22: 0 | AF22: 0 | AG22: 0 | AH22: =SUM(C22:AG22) -> 0
A23: Leche de soya | B23: =AH23/$AH$10 -> 0.0075762915 | C23: 0 | D23: 0 | E23: 0 | F23: 0 | G23: 0 | H23: 0 | I23: =129424+5522 -> 134946 | J23: 0 | K23: 0 | L23: 0 | M23: 0 | N23: 0 | O23: 0 | P23: 0 | Q23: 0 | R23: 0 | S23: 0 | T23: 0 | U23: 0 | V23: 0 | W23: 0 | X23: 0 | Y23: 0 | Z23: 0 | AA23: 0 | AB23: 0 | AC23: 0 | AD23: 141134 | AE23: 0 | AF23: 0 | AG23: 0 | AH23: =SUM(C23:AG23) -> 276080
A24: Bebestibles | B24: =AH24/$AH$10 -> 0.0021832057 | C24: 0 | D24: 0 | E24: 0 | F24: 56351 | G24: 0 | H24: 0 | I24: 23205 | J24: 0 | K24: 0 | L24: 0 | M24: 0 | N24: 0 | O24: 0 | P24: 0 | Q24: 0 | R24: 0 | S24: 0 | T24: 0 | U24: 0 | V24: 0 | W24: 0 | X24: 0 | Y24: 0 | Z24: 0 | AA24: 0 | AB24: 0 | AC24: 0 | AD24: 0 | AE24: 0 | AF24: 0 | AG24: 0 | AH24: =SUM(C24:AG24) -> 79556
A25: Brugga | B25: =AH25/$AH$10 -> 0.0077591675 | C25: 0 | D25: 0 | E25: 0 | F25: 0 | G25: 0 | H25: 0 | I25: 0 | J25: 0 | K25: 0 | L25: 0 | M25: 0 | N25: 0 | O25: 0 | P25: 188496 | Q25: 0 | R25: 0 | S25: 0 | T25: 0 | U25: 0 | V25: 0 | W25: 0 | X25: 0 | Y25: 0 | Z25: 0 | AA25: 0 | AB25: 0 | AC25: 0 | AD25: 94248 | AE25: 0 | AF25: 0 | AG25: 0 | AH25: =SUM(C25:AG25) -> 282744
A26: Colación | B26: =AH26/$AH$10 -> 0.0087845519 | C26: 0 | D26: 42743 | E26: 0 | F26: 0 | G26: 12500 | H26: 10000 | I26: 0 | J26: 0 | K26: 46870 | L26: 0 | M26: 0 | N26: 0 | O26: 17033 | P26: 0 | Q26: 0 | R26: 49508 | S26: 0 | T26: 30418 | U26: 0 | V26: 0 | W26: 0 | X26: 0 | Y26: 40391 | Z26: 0 | AA26: 12634 | AB26: 0 | AC26: 0 | AD26: 58012 | AE26: 0 | AF26: 0 | AG26: 0 | AH26: =SUM(C26:AG26) -> 320109
A27: Empaques y desechables | B27: =AH27/$AH$10 -> 0.01797805 | C27: 122308 | D27: 0 | E27: 0 | F27: 0 | G27: 0 | H27: 0 | I27: 0 | J27: 0 | K27: 0 | L27: =71960+8420 -> 80380 | M27: 0 | N27: 0 | O27: 0 | P27: 156794 | Q27: 0 | R27: 0 | S27: 0 | T27: 0 | U27: 0 | V27: 0 | W27: 0 | X27: 0 | Y27: 137136 | Z27: =6350+47622 -> 53972 | AA27: 0 | AB27: 0 | AC27: 0 | AD27: 0 | AE27: 104530 | AF27: 0 | AG27: 0 | AH27: =SUM(C27:AG27) -> 655120
A28: Soyas sachet | B28: =AH28/$AH$10 -> 0.0049394632 | C28: 89997 | D28: 0 | E28: 0 | F28: 0 | G28: 0 | H28: 0 | I28: 0 | J28: 0 | K28: 0 | L28: 0 | M28: 0 | N28: 0 | O28: 0 | P28: 0 | Q28: 0 | R28: 0 | S28: 0 | T28: 0 | U28: 89997 | V28: 0 | W28: 0 | X28: 0 | Y28: 0 | Z28: 0 | AA28: 0 | AB28: 0 | AC28: 0 | AD28: 0 | AE28: 0 | AF28: 0 | AG28: 0 | AH28: =SUM(C28:AG28) -> 179994
A29: Servilletas | B29: =AH29/$AH$10 -> 0 | C29: 0 | D29: 0 | E29: 0 | F29: 0 | G29: 0 | H29: 0 | I29: 0 | J29: 0 | K29: 0 | L29: 0 | M29: 0 | N29: 0 | O29: 0 | P29: 0 | Q29: 0 | R29: 0 | S29: 0 | T29: 0 | U29: 0 | V29: 0 | W29: 0 | X29: 0 | Y29: 0 | Z29: 0 | AA29: 0 | AB29: 0 | AC29: 0 | AD29: 0 | AE29: 0 | AF29: 0 | AG29: 0 | AH29: =SUM(C29:AG29) -> 0
A30: Limpieza e higiene | B30: =AH30/$AH$10 -> 0.0026252201 | C30: 0 | D30: 0 | E30: =3500+900+2800+5000 -> 12200 | F30: 0 | G30: 0 | H30: 0 | I30: 0 | J30: 43983 | K30: 0 | L30: 0 | M30: 0 | N30: 0 | O30: 0 | P30: 0 | Q30: 0 | R30: 0 | S30: 0 | T30: 0 | U30: 20000 | V30: 0 | W30: 0 | X30: 0 | Y30: 7980 | Z30: 3000 | AA30: 0 | AB30: 0 | AC30: 5000 | AD30: =1800+1700 -> 3500 | AE30: 0 | AF30: 0 | AG30: 0 | AH30: =SUM(C30:AG30) -> 95663
A31: Postres | B31: =AH31/$AH$10 -> 0.010856698 | C31: 0 | D31: 0 | E31: 0 | F31: 0 | G31: 0 | H31: 0 | I31: 80400 | J31: 0 | K31: 0 | L31: 0 | M31: 0 | N31: 0 | O31: 241218 | P31: 0 | Q31: 0 | R31: 0 | S31: 0 | T31: 0 | U31: 74000 | V31: 0 | W31: 0 | X31: 0 | Y31: 0 | Z31: 0 | AA31: 0 | AB31: 0 | AC31: 0 | AD31: 0 | AE31: 0 | AF31: 0 | AG31: 0 | AH31: =SUM(C31:AG31) -> 395618
A33: Gastos FV | B33: =AH33/$AH$10 -> 0.22701385 | C33: =sum(C34+C54+C64) -> 0 | D33: =sum(D34+D54+D64) -> 0 | E33: =sum(E34+E54+E64) -> 68735 | F33: =sum(F34+F54+F64) -> 60000 | G33: =sum(G34+G54+G64) -> 0 | H33: =sum(H34+H54+H64) -> 318870 | I33: =sum(I34+I54+I64) -> 1832719 | J33: =sum(J34+J54+J64) -> 3951 | ... AH33: =sum(AH34+AH54+AH64) -> 8272383
A34: Operaciones | B34: =AH34/$AH$10 -> 0.19234636 | C34: =sum(C35:C53) -> 0 | D34: =sum(D35:D53) -> 0 | E34: =sum(E35:E53) -> 0 | F34: =sum(F35:F53) -> 0 | G34: =sum(G35:G53) -> 0 | H34: =sum(H35:H53) -> 209823 | I34: =sum(I35:I53) -> 1832719 | J34: =sum(J35:J53) -> 0 | ... AH34: =sum(AH35:AH53) -> 7009100
A35: Electricidad | B35: =AH35/$AH$10 -> 0.037938949 | C35: 0 | D35: 0 | E35: 0 | F35: 0 | G35: 0 | H35: 0 | I35: 0 | J35: 0 | K35: 0 | L35: 0 | M35: 0 | N35: 0 | O35: 0 | P35: 0 | Q35: 0 | R35: 0 | S35: =363919+131378 -> 495297 | T35: 0 | U35: 0 | V35: 0 | W35: 0 | X35: 0 | Y35: 0 | Z35: 0 | AA35: 887198 | AB35: 0 | AC35: 0 | AD35: 0 | AE35: 0 | AF35: 0 | AG35: 0 | AH35: =SUM(C35:AG35) -> 1382495
A36: Agua | B36: =AH36/$AH$10 -> 0.0015079586 | C36: 0 | D36: 0 | E36: 0 | F36: 0 | G36: 0 | H36: 0 | I36: 0 | J36: 0 | K36: 0 | L36: 0 | M36: 0 | N36: 0 | O36: 0 | P36: 0 | Q36: 0 | R36: 0 | S36: 54950 | T36: 0 | U36: 0 | V36: 0 | W36: 0 | X36: 0 | Y36: 0 | Z36: 0 | AA36: 0 | AB36: 0 | AC36: 0 | AD36: 0 | AE36: 0 | AF36: 0 | AG36: 0 | AH36: =SUM(C36:AG36) -> 54950
A37: Gas | B37: =AH37/$AH$10 -> 0.0097425927 | C37: 0 | D37: 0 | E37: 0 | F37: 0 | G37: 0 | H37: 0 | I37: 0 | J37: 0 | K37: 0 | L37: 0 | M37: 0 | N37: 0 | O37: 0 | P37: 0 | Q37: 0 | R37: 0 | S37: 355020 | T37: 0 | U37: 0 | V37: 0 | W37: 0 | X37: 0 | Y37: 0 | Z37: 0 | AA37: 0 | AB37: 0 | AC37: 0 | AD37: 0 | AE37: 0 | AF37: 0 | AG37: 0 | AH37: =SUM(C37:AG37) -> 355020
A38: Restaurantpe | B38: =AH38/$AH$10 -> 0 | C38: 0 | D38: 0 | E38: 0 | F38: 0 | G38: 0 | H38: 0 | I38: 0 | J38: 0 | K38: 0 | L38: 0 | M38: 0 | N38: 0 | O38: 0 | P38: 0 | Q38: 0 | R38: 0 | S38: 0 | T38: 0 | U38: 0 | V38: 0 | W38: 0 | X38: 0 | Y38: 0 | Z38: 0 | AA38: 0 | AB38: 0 | AC38: 0 | AD38: 0 | AE38: 0 | AF38: 0 | AG38: 0 | AH38: =SUM(C38:AG38) -> 0
A39: Toteat | B39: =AH39/$AH$10 -> 0.0057580419 | C39: 0 | D39: 0 | E39: 0 | F39: 0 | G39: 0 | H39: =90777+119046 -> 209823 | I39: 0 | J39: 0 | K39: 0 | L39: 0 | M39: 0 | N39: 0 | O39: 0 | P39: 0 | Q39: 0 | R39: 0 | S39: 0 | T39: 0 | U39: 0 | V39: 0 | W39: 0 | X39: 0 | Y39: 0 | Z39: 0 | AA39: 0 | AB39: 0 | AC39: 0 | AD39: 0 | AE39: 0 | AF39: 0 | AG39: 0 | AH39: =SUM(C39:AG39) -> 209823
A40: Alarma | B40: =AH40/$AH$10 -> 0.0013141057 | C40: 0 | D40: 0 | E40: 0 | F40: 0 | G40: 0 | H40: 0 | I40: 0 | J40: 0 | K40: 0 | L40: 0 | M40: 0 | N40: 0 | O40: 0 | P40: 0 | Q40: 0 | R40: 0 | S40: 47886 | T40: 0 | U40: 0 | V40: 0 | W40: 0 | X40: 0 | Y40: 0 | Z40: 0 | AA40: 0 | AB40: 0 | AC40: 0 | AD40: 0 | AE40: 0 | AF40: 0 | AG40: 0 | AH40: =SUM(C40:AG40) -> 47886
